Workbook

Sheet 報酬確認シート（非表示）
B2: 【コーチの皆さんへ共有】 | T2: 切り替わったタイミングの請求金額をどうしているかを確認
B3: ①コーチング実施報告をするための集計に必要な情報を入力するシートです。セッション実施日を 「yyyy/mm/dd」の形式で入力してください。 | AA3: 統一のため1回：9000円で計算
B4: ②入力したデータを元に、セッション実施回数が「コミッション管理」のタブで自動集計されます。 | P4: 2月かどう | R4: 3月かどう | T4: 4月かどう | V4: 5月かどう | X4: 6月かどう | Z4: 7月かどう
O5: 請求回数： | P5: 1回目 | R5: 2回目 | T5: 3回目 | V5: 4回目 | X5: 5回目 | Z5: 6回目
F6: 旧カリキュラム | L6: ▼最終請求日 | O6: ▼初回セッション | P6: ▼通常セッション（セッション完了→ピンクセルに変更） | AA6: 日割り計算請求 | AB6: 請求書を見て入力・差額を算出 | AD6: 内訳
A7: no. | B7: 生徒名 | C7: ユーザーID | D7: 生徒ページ | E7: 講師 | F7: クラス名 | G7: メンター | H7: 生徒の入会日 | I7: 講義スタート日 | J7: 一次連絡 | K7: 初回通常セッション | M7: 担当コーチ | N7: アサインフィー | O7: 0 | P7: 1 | Q7: 2 | R7: 3 | S7: 4 | T7: 5 | U7: 6 | V7: 7 | W7: 8 | X7: 9 | Y7: 10 | Z7: 11 | AA7: 12 | AB7: 実際の請求金額合計 | AC7: トータル請求（税込） | AD7: 旧請求（アサインフィー込み） | AE7: 新報酬請求回数 | AF7: 新報酬満額請求 | AG7: 新報酬日割り請求回数 | AH7: 新報酬日割り請求額 | AI7: 確認列 | AJ7: 最終セッション | AK7: 最終請求月
A8: 1 | B8: おのまこと | C8: https://www.instagram.com/koji_no_chie?igsh=MTlhMjVlZWY5amRkeg== | D8: https://www.notion.so/f-737444a6e90e4062b518aa81f931d776?pvs=4 | E8: 駒居 | F8: F組 | G8: 駒居 | H8: 45242 | I8: 45255 | K8: =P8 -> 5000 | L8: - | M8: 宮田友理_1 | N8: 5000 | O8: 5000 | P8: 5000 | Q8: 5000 | R8: 5000 | S8: 5000 | T8: 5000 | U8: 休会 | AC8: =sum(N8:AA8) -> 35000 | AD8: =sum(N8:T8) -> 35000 | AE8: 0 | AF8: =18000*AE8 -> 0 | AG8: 0 | AH8: 0 | AI8: =sum(AD8,AF8,AH8) -> 35000 | AJ8: =vlookup(A8,'セッション実施状況管理'!$A:$AH,26,false) -> 45316
A9: 2 | B9: ただゆうすけ | C9: https://www.instagram.com/cya__home?igsh=NzZwaHVzcnN1bGtx | D9: https://www.notion.so/f-6bc9cdd93a074de893311d8592e4ea8f?pvs=4 | E9: 駒居 | F9: F組 | G9: 駒居 | H9: 45246 | I9: 45255 | K9: =P9 -> 5000 | L9: 45460 | M9: 中村恵理_1 | N9: 5000 | O9: 5000 | P9: 5000 | Q9: 5000 | R9: 5000 | S9: 5000 | T9: 5000 | U9: 5000 | V9: 5000 | W9: 5000 | X9: 18000 | Y9: 0 | Z9: 18000 | AA9: 0 | AC9: =sum(N9:AA9) -> 86000 | AD9: =sum(N9:W9) -> 50000 | AE9: 2 | AF9: =18000*AE9 -> 36000 | AG9: 0 | AH9: 0 | AI9: =sum(AD9,AF9,AH9) -> 86000 | AJ9: =vlookup(A9,'セッション実施状況管理'!$A:$AH,26,false) -> 45335 | AK9: 8月
A10: 3 | B10: ふじたなな | C10: https://www.instagram.com/ta_ma_diet/ | D10: https://www.notion.so/g-f905aeb65a5b41d2bd8e8e578a505b09?pvs=4 | E10: 駒居 | F10: G組 | G10: 駒居 | H10: 45258 | I10: 45271 | K10: =P10 -> 5000 | L10: 45455 | M10: 森本風花_1 | N10: 5000 | O10: 5000 | P10: 5000 | Q10: 5000 | R10: 5000 | S10: 5000 | T10: 5000 | U10: 5000 | V10: 5000 | W10: 5000 | X10: 5000 | Y10: 18000 | Z10: 0 | AA10: 9000 | AC10: =sum(N10:AA10) -> 82000 | AD10: =sum(N10:X10) -> 55000 | AE10: 1 | AF10: =18000*AE10 -> 18000 | AG10: 1 | AH10: =18000*(12/30) -> 7200 | AI10: =sum(AD10,AF10,AH10) -> 80200 | AJ10: =vlookup(A10,'セッション実施状況管理'!$A:$AH,26,false) -> 45331 | AK10: 7月
A11: 4 | B11: よしだむつみ | D11: https://www.notion.so/g-bb484bedf0da44c3a9204e56c3708820?pvs=4 | E11: 駒居 | F11: G組 | G11: 駒居 | H11: 45270 | I11: 45271 | K11: =P11 -> 5000 | L11: 45466 | M11: 野村佑佳_1 | N11: 5000 | O11: 5000 | P11: 5000 | Q11: 5000 | R11: 5000 | S11: 5000 | T11: 5000 | U11: 5000 | V11: 5000 | W11: 5000 | X11: 5000 | Y11: 5000 | Z11: 18000 | AA11: 0 | AC11: =sum(N11:AA11) -> 78000 | AD11: =sum(N11:Y11) -> 60000 | AE11: 1 | AF11: =18000*AE11 -> 18000 | AG11: 0 | AH11: 0 | AI11: =sum(AD11,AF11,AH11) -> 78000 | AJ11: =vlookup(A11,'セッション実施状況管理'!$A:$AH,26,false) -> 45321 | AK11: 7月
A12: 5 | B12: きたがわたかひろ | D12: https://www.notion.so/A-48b87799aff1416cbb3a1970912131a3?pvs=4 | E12: けい | F12: A組 | G12: けい | H12: 45298 | I12: 45310 | J12: 45298 | K12: =P12 -> 5000 | L12: 45130 | M12: 豊榮信江_1 | N12: 5000 | O12: 5000 | P12: 5000 | Q12: 5000 | R12: 5000 | S12: 5000 | T12: 5000 | U12: 5000 | V12: 5000 | W12: 18000 | X12: 0 | Y12: 18000 | Z12: 0 | AA12: 9000 | AC12: =sum(N12:AA12) -> 90000 | AD12: =sum(N12:V12) -> 45000 | AE12: 2 | AF12: =18000*AE12 -> 36000 | AG12: 1 | AH12: =18000*(23/30) -> 13800 | AI12: =sum(AD12,AF12,AH12) -> 94800 | AJ12: =vlookup(A12,'セッション実施状況管理'!$A:$AH,26,false) -> 45369 | AK12: 8月
A13: 6 | B13: ありやまゆうな | D13: https://www.notion.so/h-2df374753777409caed7a8803b749bdc | E13: 駒居 | F13: H組 | G13: 駒居 | H13: 45298 | I13: 45320 | K13: =P13 -> 5000 | L13: =K13+180 -> 5180 | M13: 野村佑佳_2 | N13: 5000 | O13: 5000 | P13: 5000 | Q13: 5000 | R13: 5000 | S13: 5000 | T13: 5000 | U13: 5000 | V13: 18000 | W13: 0 | X13: 18000 | Y13: 0 | Z13: 18000 | AA13: 0 | AC13: =SUM(N13:AA13) -> 94000
A14: 7 | B14: たけにしゆかり | C14: https://www.instagram.com/yukari_instakigyo?igsh=MWc1YWV0NHF3anIweA== | D14: https://www.notion.so/H-a94b7996758f4e3c9ddb2a8211a4098c?pvs=4 | E14: 駒居 | F14: H組 | G14: 駒居 | H14: 45299 | I14: 45320 | K14: =P14 -> 5000 | L14: 45503 | M14: 宮田友理_2 | N14: 5000 | O14: 5000 | P14: 5000 | Q14: 5000 | R14: 5000 | S14: 5000 | T14: 5000 | U14: 5000 | V14: 18000 | W14: 0 | X14: 18000 | Y14: 0 | Z14: 18000 | AA14: 0 | AC14: =sum(N14:AA14) -> 94000 | AD14: =sum(N14:U14) -> 40000 | AE14: 3 | AF14: =18000*AE14 -> 54000 | AG14: 0 | AH14: 0 | AI14: =sum(AD14,AF14,AH14) -> 94000 | AJ14: =vlookup(A14,'セッション実施状況管理'!$A:$AH,26,false) -> 45376 | AK14: 8月
A15: 8 | B15: くどうゆみこ | D15: https://www.notion.so/C-1b937693667844edb42ba0b3f91eb95a | E15: しらゆき | F15: D組 | G15: しらゆき | H15: 45313 | I15: 2月上旬 | J15: 45315 | K15: =P15 -> 5000 | L15: 45521 | M15: 野村佑佳_3 | N15: 5000 | O15: 5000 | P15: 5000 | Q15: 5000 | R15: 5000 | S15: 5000 | T15: 5000 | U15: 18000 | V15: 0 | W15: 18000 | X15: 0 | Y15: 18000 | Z15: 0 | AA15: 9000 | AC15: =sum(N15:AA15) -> 98000 | AD15: =sum(N15:T15) -> 35000 | AE15: 3 | AF15: =18000*AE15 -> 54000 | AG15: 1 | AH15: =18000*(17/30) -> 10200 | AI15: =sum(AD15,AF15,AH15) -> 99200 | AJ15: =vlookup(A15,'セッション実施状況管理'!$A:$AH,26,false) -> 45390
A16: 9 | B16: たわらかずみ | D16: https://www.notion.so/H-6c47c382fb41416bb5398a08d0efa69a?pvs=4 | E16: ソウタ | F16: H組 | G16: いとた | H16: 45314 | I16: 2月上旬 | K16: =P16 -> 5000 | L16: 45515 | M16: 中村恵理_2 | N16: 5000 | O16: 5000 | P16: 5000 | Q16: 5000 | R16: 5000 | S16: 5000 | T16: 5000 | U16: 5000 | V16: 18000 | W16: 0 | X16: 18000 | Y16: 0 | Z16: 18000 | AA16: 0 | AC16: =sum(N16:AA16) -> 94000 | AD16: =sum(N16:U16) -> 40000 | AE16: 3 | AF16: =18000*AE16 -> 54000 | AG16: 0 | AH16: 0 | AI16: =sum(AD16,AF16,AH16) -> 94000 | AJ16: =vlookup(A16,'セッション実施状況管理'!$A:$AH,26,false) -> 45387
A17: 10 | B17: やまぐちしんいちろう | D17: https://www.notion.so/h-4ee1213842f34a8abc522b1b681bf0a8?pvs=4 | E17: ソウタ | F17: H組 | G17: いとた | H17: 45317 | I17: 2月上旬 | J17: 45319 | K17: =P17 -> 5000 | L17: 45514 | M17: 森本風花_2 | N17: 5000 | O17: 5000 | P17: 5000 | Q17: 5000 | R17: 5000 | S17: 5000 | T17: 5000 | U17: 5000 | V17: 18000 | W17: 0 | X17: 18000 | Y17: 0 | Z17: 18000 | AA17: 0 | AC17: =sum(N17:AA17) -> 94000 | AD17: =sum(N17:U17) -> 40000 | AE17: 3 | AF17: =18000*AE17 -> 54000 | AG17: 0 | AH17: 0 | AI17: =sum(AD17,AF17,AH17) -> 94000 | AJ17: =vlookup(A17,'セッション実施状況管理'!$A:$AH,26,false) -> 45375 | AK17: 8月
A18: 11 | B18: かわかみまさと | D18: https://www.notion.so/C-4f2fdb58942d4be1b66b12e294a78cce | E18: しらゆき | F18: C組 | G18: しらゆき | H18: 45320 | I18: 2月上旬 | J18: 45320 | K18: =P18 -> 5000 | L18: 45520 | M18: 野村佑佳_4 | N18: 5000 | O18: 5000 | P18: 5000 | Q18: 5000 | R18: 5000 | S18: 5000 | T18: 5000 | U18: 18000 | V18: 0 | W18: 18000 | X18: 0 | Y18: 18000 | Z18: 0 | AA18: 9000 | AC18: =sum(N18:AA18) -> 98000 | AD18: =sum(N18:T18) -> 35000 | AE18: 3 | AF18: =18000*AE18 -> 54000 | AG18: 1 | AH18: =18000*(16/30) -> 9600 | AI18: =sum(AD18,AF18,AH18) -> 98600 | AJ18: =vlookup(A18,'セッション実施状況管理'!$A:$AH,26,false) -> 45389
A19: 12 | B19: すどうえり | C19: https://www.instagram.com/richan_hair?igsh=b2oxMXgybGl5NGNj&utm_source=qr | D19: https://www.notion.so/h-75b166b01bdd4a7dab2f816f840c40f6?pvs=4 | E19: ソウタ | F19: H組 | G19: いとた | H19: 45320 | I19: 2月上旬 | J19: 45320 | K19: =P19 -> 5000 | L19: 45514 | M19: 宮田友理_3 | N19: 5000 | O19: 5000 | P19: 5000 | Q19: 5000 | R19: 5000 | S19: 5000 | T19: 5000 | U19: 18000 | V19: 0 | W19: 18000 | X19: 0 | Y19: 18000 | Z19: 0 | AA19: 9000 | AC19: =sum(N19:AA19) -> 98000 | AD19: =sum(N19:T19) -> 35000 | AE19: 3 | AF19: =18000*AE19 -> 54000 | AG19: 1 | AH19: =18000*(10/30) -> 6000 | AI19: =sum(AD19,AF19,AH19) -> 95000 | AJ19: =vlookup(A19,'セッション実施状況管理'!$A:$AH,26,false) -> 45400 | AK19: 9月
A20: 13 | B20: なかのあや | D20: https://www.notion.so/C-18ef10444b5245ea9a00a9fa9f6aa26f?pvs=4 | E20: しらゆき | F20: C組 | G20: しらゆき | H20: 45325 | I20: 2月上旬 | J20: 45325 | K20: =P20 -> 5000 | L20: 45527 | M20: 清原三和子_1 | N20: 5000 | O20: 5000 | P20: 5000 | Q20: 5000 | R20: 5000 | S20: 5000 | T20: 5000 | U20: 18000 | V20: 0 | W20: 18000 | X20: 0 | Y20: 18000 | Z20: 0 | AA20: 9000 | AC20: =sum(N20:AA20) -> 98000 | AD20: =sum(N20:T20) -> 35000 | AE20: 3 | AF20: =18000*AE20 -> 54000 | AG20: 1 | AH20: =18000*(23/30) -> 13800 | AI20: =sum(AD20,AF20,AH20) -> 102800 | AJ20: =vlookup(A20,'セッション実施状況管理'!$A:$AH,26,false) -> 45388 | AK20: 8月
A21: 14 | B21: うちだあやみ | D21: https://www.notion.so/B-daf8c007896a46c19df1d51b7331b579?pvs=4 | E21: けいいち | F21: B組 | G21: けいいち | H21: 45326 | I21: 2月中旬 | J21: 45326 | K21: =P21 -> 5000 | L21: 45526 | M21: 清原三和子_2 | N21: 5000 | O21: 5000 | P21: 5000 | Q21: 5000 | R21: 5000 | S21: 5000 | T21: 5000 | U21: 18000 | V21: 0 | W21: 18000 | X21: 0 | Y21: 18000 | Z21: 0 | AA21: 9000 | AC21: =sum(N21:AA21) -> 98000 | AD21: =sum(N21:T21) -> 35000 | AE21: 3 | AF21: =18000*AE21 -> 54000 | AG21: 1 | AH21: =18000*(22/30) -> 13200 | AI21: =sum(AD21,AF21,AH21) -> 102200 | AJ21: =vlookup(A21,'セッション実施状況管理'!$A:$AH,26,false) -> 45388 | AK21: 8月
A22: 15 | B22: さかもとなみこ | D22: https://www.notion.so/A-30616aeef36d46609bace7715472cba9 | E22: ふみや | F22: A組 | G22: ふみや | H22: 45328 | I22: 45335 | J22: 45328 | K22: =P22 -> 5000 | L22: 45520 | M22: 山見阪佳子_1 | N22: 5000 | O22: 5000 | P22: 5000 | Q22: 5000 | R22: 5000 | S22: 5000 | T22: 5000 | U22: 5000 | V22: 18000 | W22: 0 | X22: 18000 | Y22: 0 | Z22: 18000 | AA22: 0 | AC22: =sum(N22:AA22) -> 94000 | AD22: =sum(N22:U22) -> 40000 | AE22: 3 | AF22: =18000*AE22 -> 54000 | AG22: 0 | AH22: 0 | AI22: =sum(AD22,AF22,AH22) -> 94000 | AJ22: =vlookup(A22,'セッション実施状況管理'!$A:$AH,26,false) -> 202403/30 | AK22: 8月
A23: 16 | B23: あいざわくみこ | D23: https://www.notion.so/A-49f636e8bc784058b509202e308d986d?pvs=4 | E23: ふみや | F23: A組 | G23: ふみや | H23: 45328 | I23: 2月中旬 | J23: 45328 | K23: =P23 -> 5000 | L23: 45531 | M23: 清原三和子_3 | N23: 5000 | O23: 5000 | P23: 5000 | Q23: 5000 | R23: 5000 | S23: 5000 | T23: 5000 | U23: 5000 | V23: 18000 | W23: 0 | X23: 18000 | Y23: 0 | Z23: 18000 | AA23: 0 | AC23: =sum(N23:AA23) -> 94000 | AD23: =sum(N23:U23) -> 40000 | AE23: 3 | AF23: =18000*AE23 -> 54000 | AG23: 0 | AH23: 0 | AI23: =sum(AD23,AF23,AH23) -> 94000 | AJ23: =vlookup(A23,'セッション実施状況管理'!$A:$AH,26,false) -> 45384 | AK23: 8月
A24: 17 | B24: よこやまあいと | E24: ふみや | F24: B組 | G24: ふみや | H24: 45330 | I24: 2月中旬 | J24: 45330 | K24: =P24 -> 5000 | L24: 45540 | M24: 福田康裕_1 | N24: 5000 | O24: 5000 | P24: 5000 | Q24: 5000 | R24: 18000 | S24: 0 | T24: 18000 | U24: 0 | V24: 18000 | W24: 0 | X24: 18000 | Y24: 0 | Z24: 18000 | AA24: 0 | AC24: =sum(N24:AA24) -> 110000 | AD24: =sum(N24:Q24) -> 20000 | AE24: 5 | AF24: =18000*AE24 -> 90000 | AG24: 0 | AH24: 0 | AI24: =sum(AD24,AF24,AH24) -> 110000 | AJ24: =vlookup(A24,'セッション実施状況管理'!$A:$AH,26,false) -> 45445
A25: 18 | B25: ふちがみあや | D25: https://www.notion.so/c7b88ab6a5674a1cb0260e9c208c019a | E25: ふみや | F25: B組 | G25: ふみや | H25: 45330 | I25: 2月中旬 | J25: 45330 | K25: =P25 -> 5000 | L25: 45530 | M25: 山見阪佳子_2 | N25: 5000 | O25: 5000 | P25: 5000 | Q25: 5000 | R25: 5000 | S25: 5000 | T25: 18000 | U25: 0 | V25: 18000 | W25: 0 | X25: 18000 | Y25: 0 | Z25: 18000 | AA25: 0 | AC25: =sum(N25:AA25) -> 102000 | AD25: =sum(N25:S25) -> 30000 | AE25: 4 | AF25: =18000*AE25 -> 72000 | AG25: 0 | AH25: 0 | AI25: =sum(AD25,AF25,AH25) -> 102000 | AJ25: =vlookup(A25,'セッション実施状況管理'!$A:$AH,26,false) -> 45397
A26: 19 | B26: おおにしちかこ | E26: ソウタ | F26: J組 | G26: ハム | H26: 45347 | I26: 3月上旬〜中旬 | J26: 45348 | K26: =P26 -> 5000 | L26: 45592 | M26: 須見浩人_1 | N26: 5000 | O26: 5000 | P26: 5000 | Q26: 18000 | R26: 0 | S26: 18000 | T26: 0 | U26: 18000 | V26: 0 | W26: 18000 | X26: 0 | Y26: 18000 | Z26: 0 | AA26: 9000 | AC26: =sum(N26:AA26) -> 114000 | AD26: =sum(N26:P26) -> 15000 | AE26: 5 | AF26: =18000*AE26 -> 90000 | AG26: 1 | AH26: =18000*(27/30) -> 16200 | AI26: =sum(AD26,AF26,AH26) -> 121200 | AJ26: =vlookup(A26,'セッション実施状況管理'!$A:$AH,26,false) -> 45481
A27: 20 | B27: すだはるき | E27: 村松 | F27: E組 | G27: 村松 | H27: 45385 | I27: 4月下旬 | J27: 45385 | K27: =P27 -> 5000 | L27: 45594 | M27: 須見浩人_2 | N27: 5000 | O27: 5000 | P27: 5000 | Q27: 18000 | R27: 0 | S27: 18000 | T27: 0 | U27: 18000 | V27: 0 | W27: 18000 | X27: 0 | Y27: 18000 | Z27: 0 | AA27: 9000 | AC27: =sum(N27:AA27) -> 114000 | AD27: =sum(N27:P27) -> 15000 | AE27: 5 | AF27: =18000*AE27 -> 90000 | AG27: 0 | AH27: =18000*(29/30) -> 17400 | AI27: =sum(AD27,AF27,AH27) -> 122400 | AJ27: =vlookup(A27,'セッション実施状況管理'!$A:$AH,26,false) -> 45477
A28: 21 | B28: かしはらせつみ | E28: ソウタ | F28: L組 | G28: 村松 | H28: 45392 | I28: 4月下旬 | J28: 45392 | K28: =P28 -> 18000 | L28: 45586 | M28: 宮田友理_4 | N28: 5000 | O28: 5000 | P28: 18000 | Q28: 0 | R28: 18000 | S28: 0 | T28: 18000 | U28: 0 | V28: 18000 | W28: 0 | X28: 18000 | Y28: 0 | Z28: 18000 | AA28: 0 | AC28: =sum(N28:AA28) -> 118000 | AD28: =sum(N28:O28) -> 10000 | AE28: 5 | AF28: =18000*AE28 -> 90000 | AG28: 0 | AI28: =sum(AD28,AF28,AH28) -> 100000 | AJ28: =vlookup(A28,'セッション実施状況管理'!$A:$AH,26,false) -> 45455 | AK28: 11月
A29: 22 | B29: ながおあみり | E29: 村松 | F29: F組 | G29: 村松 | H29: 45409 | I29: 5月中旬 | K29: =P29 -> 18000 | L29: 45615 | M29: 野村佑佳_5 | N29: - | O29: 0 | P29: 18000 | Q29: 0 | R29: 18000 | S29: 0 | T29: 18000 | U29: 0 | V29: 18000 | W29: 0 | X29: 18000 | Y29: 0 | Z29: 18000 | AA29: 0 | AC29: =sum(N29:AA29) -> 108000 | AD29: 0 | AE29: 6 | AF29: =18000*AE29 -> 108000 | AG29: 0 | AH29: 0 | AI29: =sum(AD29,AF29,AH29) -> 108000 | AJ29: =vlookup(A29,'セッション実施状況管理'!$A:$AH,26,false) -> 45491
A30: 23 | B30: こばやしはるか | E30: 村松 | F30: F組 | G30: 村松 | H30: 45411 | I30: 5月中旬 | J30: 45414 | K30: =P30 -> 18000 | L30: 45629 | M30: 清原三和子_4 | N30: - | O30: 0 | P30: 18000 | Q30: 0 | R30: 18000 | S30: 0 | T30: 18000 | U30: 0 | V30: 18000 | W30: 0 | X30: 18000 | Y30: 0 | Z30: 18000 | AA30: 0 | AC30: =sum(N30:AA30) -> 108000 | AD30: 0 | AE30: 6 | AF30: =18000*AE30 -> 108000 | AG30: 0 | AH30: 0 | AI30: =sum(AD30,AF30,AH30) -> 108000 | AJ30: =vlookup(A30,'セッション実施状況管理'!$A:$AH,26,false) -> 45491
A31: 24 | B31: じょうどじゆうき | E31: けいいち | F31: C組 | G31: けいいち | H31: 45429 | I31: 6月上旬 | K31: =P31 -> 18000 | L31: 180 | M31: 福田康裕_2 | N31: - | O31: 0 | P31: 18000 | Q31: 0 | R31: 18000 | S31: 0 | T31: 18000 | U31: 0 | V31: 18000 | W31: 0 | X31: 18000 | Y31: 0 | Z31: 18000 | AA31: 0 | AC31: =sum(N31:AA31) -> 108000 | AD31: 0 | AE31: 6 | AF31: =18000*AE31 -> 108000 | AG31: 0 | AH31: 0 | AI31: =sum(AD31,AF31,AH31) -> 108000 | AJ31: =vlookup(A31,'セッション実施状況管理'!$A:$AH,26,false)
A32: 25 | B32: たなかゆりか | E32: けいいち | F32: C組 | G32: けいいち | H32: 45430 | I32: 6月上旬 | J32: 45433 | K32: =P32 | L32: 180 | M32: 清原三和子_5 | N32: - | O32: 5000 | AC32: =sum(N32:AA32) -> 5000 | AD32: 0 | AE32: 6 | AF32: =18000*AE32 -> 108000 | AG32: 0 | AH32: 0 | AI32: =sum(AD32,AF32,AH32) -> 108000 | AJ32: =vlookup(A32,'セッション実施状況管理'!$A:$AH,26,false)
A33: 26 | B33: かわしま あらし | E33: 村松 | F33: G組 | G33: 村松 | H33: 45434 | I33: 6月上旬 | K33: =P33 -> 18000 | L33: 45634 | M33: 森本風花_3 | N33: - | O33: 0 | P33: 18000 | Q33: 0 | R33: 18000 | S33: 0 | T33: 18000 | U33: 0 | V33: 18000 | W33: 0 | X33: 18000 | Y33: 0 | Z33: 18000 | AA33: 0 | AC33: =sum(N33:AA33) -> 108000 | AD33: 0 | AE33: 6 | AF33: =18000*AE33 -> 108000 | AG33: 0 | AH33: 0 | AI33: =sum(AD33,AF33,AH33) -> 108000 | AJ33: =vlookup(A33,'セッション実施状況管理'!$A:$AH,26,false) -> 45496
A34: 27 | B34: せきおかまさき | E34: ふみや | F34: C組 | G34: ふみや | H34: 45438 | I34: 6月上旬 | K34: =P34 -> 18000 | L34: 180 | M34: 福田康裕_3 | N34: - | O34: 0 | P34: 18000 | Q34: 0 | R34: 18000 | S34: 0 | T34: 18000 | U34: 0 | V34: 18000 | W34: 0 | X34: 18000 | Y34: 0 | Z34: 18000 | AA34: 0 | AC34: =sum(N34:AA34) -> 108000 | AD34: 0 | AE34: 6 | AF34: =18000*AE34 -> 108000 | AG34: 0 | AH34: 0 | AI34: =sum(AD34,AF34,AH34) -> 108000 | AJ34: =vlookup(A34,'セッション実施状況管理'!$A:$AH,26,false)
A35: 28 | B35: しらどうさき | E35: 未定 | F35: 未定 | G35: 未定 | H35: 45440 | I35: 出産のため7月末から受講開始を希望 | K35: =P35 | L35: =K35+180 -> 180 | O35: アサイン・クラス決めは7月末生徒さんから連絡いただき次第行う。一旦保留
A36: 29 | B36: まさきちさと | E36: ふみや | F36: C組 | G36: ふみや | H36: 45440 | I36: 6月上旬 | J36: 45441 | K36: =P36 -> 18000 | L36: 45643 | M36: 宮田友理_5 | N36: - | O36: 0 | P36: 18000 | Q36: 0 | R36: 18000 | S36: 0 | T36: 18000 | U36: 0 | V36: 18000 | W36: 0 | X36: 18000 | Y36: 0 | Z36: 18000 | AA36: 0 | AC36: =sum(N36:AA36) -> 108000 | AD36: 0 | AE36: 6 | AF36: =18000*AE36 -> 108000 | AG36: 0 | AH36: 0 | AI36: =sum(AD36,AF36,AH36) -> 108000 | AJ36: =vlookup(A36,'セッション実施状況管理'!$A:$AH,26,false) -> 45511
A37: 30 | B37: みよしゆうき | E37: ふみや | F37: C組 | G37: ふみや | H37: 45441 | I37: 6月上旬 | K37: =P37 -> 18000 | L37: 45637 | M37: 清原三和子_6 | N37: - | O37: 0 | P37: 18000 | Q37: 0 | R37: 18000 | S37: 0 | T37: 18000 | U37: 0 | V37: 18000 | W37: 0 | X37: 18000 | Y37: 0 | Z37: 18000 | AA37: 0 | AC37: =sum(N37:AA37) -> 108000 | AD37: 0 | AE37: 6 | AF37: =18000*AE37 -> 108000 | AG37: 0 | AH37: 0 | AI37: =sum(AD37,AF37,AH37) -> 108000 | AJ37: =vlookup(A37,'セッション実施状況管理'!$A:$AH,26,false) -> 45498
A38: 31 | B38: すずきかおり | E38: ハマコ | F38: A組 | G38: ハマコ | H38: 45458 | I38: 7月上旬 | K38: =P38 -> 18000 | L38: 180 | M38: 野村佑佳_6 | N38: - | O38: 0 | P38: 18000 | Q38: 0 | R38: 18000 | S38: 0 | T38: 18000 | U38: 0 | V38: 18000 | W38: 0 | X38: 18000 | Y38: 0 | Z38: 18000 | AA38: 0 | AC38: =sum(N38:AA38) -> 108000 | AD38: 0 | AE38: 6 | AF38: =18000*AE38 -> 108000 | AG38: 0 | AH38: 0 | AI38: =sum(AD38,AF38,AH38) -> 108000 | AJ38: =vlookup(A38,'セッション実施状況管理'!$A:$AH,26,false) -> 45573
A39: 32 | B39: きたがわあやの | E39: 駒居 | F39: H組 | G39: 駒居 | K39: =P39 | L39: =K39+180 -> 180
A40: 33 | B40: さんのうたかひろ | E40: 村松 | F40: H組 | G40: 村松 | H40: 45510 | I40: 8月下旬 | K40: =P40 | L40: =K40+180 -> 180
A41: 34 | B41: かどたゆきこ | E41: ノア | F41: D組 | G41: ノア | H41: 45515 | I41: 8月下旬 | K41: =P41 | L41: =K41+180 -> 180 | M41: 清原三和子_7
...

Sheet セッション実施状況管理
D1: nanami_movie_streaming
H2: 【コーチの皆さんへ共有】
H3: ①コーチング実施報告をするための集計に必要な情報を入力するシートです。セッション実施日を 「yyyy/mm/dd」の形式で入力してください。
H4: ②入力したデータを元に、セッション実施回数が「コミッション管理」のタブで自動集計されます。
B5: 合計： | C5: =counta(C11:C1028) -> 300
B6: 万垢達成率： | C6: =C7/C5*100 -> 9.3333333 | I6: コミットプランライト
B7: 万垢達成数： | C7: =COUNTIF(C11:C310,1)+COUNTIF(C11:C310,2) -> 28 | I7: https://docs.google.com/spreadsheets/d/1M0bfbCkULbFtvyCbAFnaiyuW9oN4kZkqfVYrhonlE5A/edit?gid=1649866131#gid=1649866131
B8: 卒業生数： | C8: =COUNTIF(B11:B311, "卒業") -> 82 | W8: 1ヶ月目 | Y8: 2ヶ月目 | AA8: 3ヶ月目 | AC8: 4ヶ月目 | AE8: 5ヶ月目 | AG8: 6ヶ月目
B9: 在学中： | C9: =countif(B11:B1028,"在学中") -> 194 | F9: 卒業時まで更新 | J9: ƒƒ | L9: 旧カリキュラム | S9: ▼最終日報提出日 | V9: ▼初回セッション | W9: ▼通常セッション（セッション完了→ピンクセルに変更・生徒の無断キャンセル=日付を入れて、セルを青に）
A10: no. | B10: status | C10: 万垢 | D10: 合計アクション数 | E10: 投稿開始時投稿数 | F10: 表示投稿数 | G10: 投稿数 | H10: 生徒名 | I10: user ID | J10: 生徒ページ | K10: 講師 | L10: クラス名 | M10: メンター | N10: 生徒の入会日 | O10: 講義スタート日 | P10: 面談日 | Q10: SP開始日 | R10: 1回目通常セッション | S10: 最終サポート日 | T10: 担当MG名 | U10: 列 1 | V10: 0 | W10: 1 | X10: 2 | Y10: 3 | Z10: 4 | AA10: 5 | AB10: 6 | AC10: 7 | AD10: 8 | AE10: 9 | AF10: 10 | AG10: 11 | AH10: 12 | AI10: 最終サポート日数
A11: 1 | B11: 例外 | C11: 0 | D11: 0 | E11: 0 | F11: 5 | G11: =F11-E11 -> 5 | H11: おのまこと | I11: koji_no_chie | J11: https://www.notion.so/f-737444a6e90e4062b518aa81f931d776?pvs=4 | K11: 駒居 | L11: F組 | M11: 駒居 | N11: 45242 | O11: 45255 | P11: - | Q11: - | R11: =W11 -> 45273 | S11: - | T11: 宮田友理 | U11: 1 | V11: 45259 | W11: 45273 | X11: 45287 | Y11: 45302 | Z11: 45316 | AA11: 45338 | AB11: 休会 | AI11: =IF(COUNT(AH12,V12)=2, AH12-V12, "") -> 220
A12: 2 | B12: 卒業 | C12: 1 | D12: 198 | E12: 0 | F12: 123 | G12: =F12-E12 -> 123 | H12: ただゆうすけ | I12: cya_kurashi | J12: https://www.notion.so/f-6bc9cdd93a074de893311d8592e4ea8f?pvs=4 | K12: 駒居 | L12: F組 | M12: 駒居 | N12: 45246 | O12: 45255 | P12: - | Q12: - | R12: =W12 -> 45280 | S12: =R12+180 -> 45460 | T12: 中村恵理 | U12: 1 | V12: 45260 | W12: 45280 | X12: 45305 | Y12: 45326 | Z12: 45335 | AA12: 45350 | AB12: 45364 | AC12: 45392 | AD12: 45412 | AE12: 45426 | AF12: 45445 | AG12: 45459 | AH12: 45480 | AI12: =AH12-V12 -> 220
A13: 3 | B13: 卒業 | C13: 0 | D13: 41 | E13: 0 | F13: - | G13: =F13-E13 -> #VALUE! | H13: ふじたなな | I13: ta_ma_diet | J13: https://www.notion.so/g-f905aeb65a5b41d2bd8e8e578a505b09?pvs=4 | K13: 駒居 | L13: G組 | M13: 駒居 | N13: 45258 | O13: 45271 | P13: 45625 | R13: =W13 -> 45275 | S13: =R13+180 -> 45455 | T13: 森本風花 | U13: 1 | V13: 45263 | W13: 45275 | X13: 45304 | Y13: 45315 | Z13: 45331 | AA13: 45350 | AB13: 45357 | AC13: 45372 | AD13: 45385 | AE13: 45406 | AF13: 45420 | AG13: 45435 | AH13: 45449 | AI13: =AH13-V13 -> 186
A14: 4 | B14: 卒業 | C14: 0 | D14: 74 | E14: 0 | F14: 24 | G14: =F14-E14 -> 24 | H14: よしだむつみ | I14: adhd_nao | J14: https://www.notion.so/g-bb484bedf0da44c3a9204e56c3708820?pvs=4 | K14: 駒居 | L14: G組 | M14: 駒居 | N14: 45270 | O14: 45271 | P14: 45637 | R14: =W14 -> 45286 | S14: =R14+180 -> 45466 | T14: 野村佑佳 | U14: 1 | V14: 45279 | W14: 45286 | X14: 45293 | Y14: 45307 | Z14: 45321 | AA14: 45335 | AB14: 45349 | AC14: 45363 | AD14: 45377 | AE14: 45391 | AF14: 45405 | AG14: 45447 | AH14: 45461 | AI14: =AH14-V14 -> 182
A15: 5 | B15: 卒業 | C15: 0 | D15: 119 | E15: 0 | F15: 6 | G15: =F15-E15 -> 6 | H15: きたがわたかひろ | I15: kcc_0113 | J15: https://www.notion.so/A-48b87799aff1416cbb3a1970912131a3?pvs=4 | K15: けい | L15: A組 | M15: けい | N15: 45298 | O15: 45310 | P15: 45298 | R15: =W15 -> 44950 | S15: =R15+180 -> 45130 | T15: 豊榮信江 | U15: 1 | V15: 45301 | W15: 44950 | X15: 45329 | Y15: 45343 | Z15: 45369 | AA15: 45380 | AB15: 45401 | AC15: 45408 | AD15: 45422 | AE15: 45439 | AF15: 45470 | AG15: 45487 | AH15: 45492 | AI15: =AH15-V15 -> 191
A16: 6 | B16: 卒業 | C16: 2 | D16: 539 | E16: 0 | F16: 113 | G16: =F16-E16 -> 113 | H16: ありやまゆうな | I16: uni_beer_ | J16: https://www.notion.so/h-2df374753777409caed7a8803b749bdc | K16: 駒居 | L16: H組 | M16: 駒居 | N16: 45298 | O16: 45320 | P16: 45298 | R16: =W16 -> 45336 | S16: =R16+180 -> 45516 | T16: 野村佑佳 | U16: 2 | V16: 45301 | W16: 45336 | X16: 45350 | Y16: 45370 | Z16: 45384 | AA16: 45398 | AB16: 45411 | AC16: 45426 | AD16: 45442 | AE16: 45455 | AF16: 45469 | AG16: 45483 | AH16: 45588 | AI16: =AH16-V16 -> 287
A17: 7 | B17: 卒業 | C17: 0 | D17: 17 | E17: 0 | F17: - | G17: =F17-E17 -> #VALUE! | H17: たけにしゆかり | I17: yukari_dekirumon | J17: https://www.notion.so/H-a94b7996758f4e3c9ddb2a8211a4098c?pvs=4 | K17: 駒居 | L17: H組 | M17: 駒居 | N17: 45299 | O17: 45320 | P17: 45299 | R17: =W17 -> 45323 | S17: =R17+180 -> 45503 | T17: 宮田友理 | U17: 2 | V17: 45301 | W17: 45323 | X17: 45337 | Y17: 45350 | Z17: 45376 | AA17: 45390 | AB17: 45406 | AC17: 45420 | AD17: 45434 | AE17: 45448 | AF17: 45464 | AG17: 45474 | AH17: 45489 | AI17: =AH17-V17 -> 188
A18: 8 | B18: 卒業 | C18: 0 | D18: 81 | E18: 0 | F18: - | G18: =F18-E18 -> #VALUE! | H18: くどうゆみこ | I18: くどうゆみこ | J18: https://www.notion.so/C-1b937693667844edb42ba0b3f91eb95a | K18: しらゆき | L18: D組 | M18: しらゆき | N18: 45313 | O18: 2月上旬 | P18: 45315 | R18: =W18 -> 45341 | S18: =R18+180 -> 45521 | T18: 野村佑佳 | U18: 3 | V18: 45322 | W18: 45341 | X18: 45355 | Y18: 45369 | Z18: 45390 | AA18: 45404 | AB18: 45418 | AC18: 45432 | AD18: 45446 | AE18: 45460 | AF18: 45474 | AG18: 45489 | AH18: 45509 | AI18: =AH18-V18 -> 187
A19: 9 | B19: 卒業 | C19: 0 | D19: 247 | E19: 0 | F19: 51 | G19: =F19-E19 -> 51 | H19: たわらかずみ | I19: negi_mamalife | J19: https://www.notion.so/H-6c47c382fb41416bb5398a08d0efa69a?pvs=4 | K19: ソウタ | L19: H組 | M19: いとた | N19: 45314 | O19: 2月上旬 | P19: 45315 | R19: =W19 -> 45335 | S19: =R19+180 -> 45515 | T19: 中村恵理 | U19: 2 | V19: 45319 | W19: 45335 | X19: 45349 | Y19: 45373 | Z19: 45387 | AA19: 45401 | AB19: 45411 | AC19: 45425 | AD19: 45444 | AE19: 45456 | AF19: 45469 | AG19: 45483 | AH19: 45511 | AI19: =AH19-V19 -> 192
A20: 10 | B20: 卒業 | C20: 0 | D20: 276 | E20: 0 | F20: 209 | G20: 103 | H20: やまぐちしんいちろう | I20: tewofuru_woodjewelry | J20: https://www.notion.so/h-4ee1213842f34a8abc522b1b681bf0a8?pvs=4 | K20: ソウタ | L20: H組 | M20: いとた | N20: 45317 | O20: 2月上旬 | P20: 45319 | R20: =W20 -> 45334 | S20: =R20+180 -> 45514 | T20: 森本風花 | U20: 2 | V20: 45324 | W20: 45334 | X20: 45348 | Y20: 45362 | Z20: 45375 | AA20: 45389 | AB20: 45403 | AC20: 45417 | AD20: 45431 | AE20: 45445 | AF20: 45459 | AG20: 45473 | AH20: 45494 | AI20: =AH20-V20 -> 170
A21: 11 | B21: 卒業 | C21: 0 | D21: 252 | E21: 0 | F21: 24 | G21: =F21-E21 -> 24 | H21: かわかみまさと | I21: satojitan_recipe | J21: https://www.notion.so/C-4f2fdb58942d4be1b66b12e294a78cce | K21: しらゆき | L21: C組 | M21: しらゆき | N21: 45320 | O21: 2月上旬 | P21: 45320 | R21: =W21 -> 45340 | S21: =R21+180 -> 45520 | T21: 野村佑佳 | U21: 4 | V21: 45326 | W21: 45340 | X21: 45354 | Y21: 45368 | Z21: 45389 | AA21: 45408 | AB21: 45415 | AC21: 45431 | AD21: 45444 | AE21: 45459 | AF21: 45472 | AG21: 45488 | AH21: 45507 | AI21: =AH21-V21 -> 181
A22: 12 | B22: 卒業 | C22: 0 | D22: 188 | E22: 0 | F22: 84 | G22: 18 | H22: すどうえり | I22: richan_hair | J22: https://www.notion.so/h-75b166b01bdd4a7dab2f816f840c40f6?pvs=4 | K22: ソウタ | L22: H組 | M22: いとた | N22: 45320 | O22: 2月上旬 | P22: 45320 | R22: =W22 -> 45334 | S22: =R22+180 -> 45514 | T22: 宮田友理 | U22: 3 | V22: 45324 | W22: 45334 | X22: 45343 | Y22: 45369 | Z22: 45400 | AA22: 45411 | AB22: 45441 | AC22: 45460 | AD22: 45471 | AE22: 45485 | AF22: 45504 | AG22: 45526 | AH22: 45539 | AI22: =AH22-V22 -> 215
A23: 13 | B23: 卒業 | C23: 0 | D23: 116 | E23: 0 | F23: 24 | G23: =F23-E23 -> 24 | H23: なかのあや | I23: aya_travel_europe | J23: https://www.notion.so/C-18ef10444b5245ea9a00a9fa9f6aa26f?pvs=4 | K23: しらゆき | L23: C組 | M23: しらゆき | N23: 45325 | O23: 2月上旬 | P23: 45325 | R23: =W23 -> 45347 | S23: =R23+180 -> 45527 | T23: 清原三和子 | U23: 1 | V23: 45332 | W23: 45347 | X23: 45361 | Y23: 45374 | Z23: 45388 | AA23: 45403 | AB23: 45416 | AC23: 45430 | AD23: 45444 | AE23: 45458 | AF23: 45486 | AG23: 45507 | AH23: 45519 | AI23: =AH23-V23 -> 187
A24: 14 | B24: 卒業 | C24: 1 | D24: 285 | E24: 0 | F24: 100 | G24: =F24-E24 -> 100 | H24: うちだあやみ | I24: uchiko_gohan | J24: https://www.notion.so/B-daf8c007896a46c19df1d51b7331b579?pvs=4 | K24: けいいち | L24: B組 | M24: けいいち | N24: 45326 | O24: 2月中旬 | P24: 45326 | R24: =W24 -> 45346 | S24: =R24+180 -> 45526 | T24: 清原三和子 | U24: 2 | V24: 45332 | W24: 45346 | X24: 45360 | Y24: 45374 | Z24: 45388 | AA24: 45403 | AB24: 45416 | AC24: 45434 | AD24: 45444 | AE24: 45458 | AF24: 45472 | AG24: 45484 | AH24: 45500 | AI24: =AH24-V24 -> 168
A25: 15 | B25: 卒業 | C25: 0 | D25: 250 | E25: 0 | F25: 99 | G25: =F25-E25 -> 99 | H25: さかもとなみこ | I25: hiroyukichan_renai | J25: https://www.notion.so/A-30616aeef36d46609bace7715472cba9 | K25: ふみや | L25: A組 | M25: ふみや | N25: 45328 | O25: 45335 | P25: 45328 | R25: =W25 -> 45340 | S25: =R25+180 -> 45520 | T25: 山見阪佳子 | U25: 1 | V25: 45333 | W25: 45340 | X25: 45353 | Y25: 45371 | Z25: 202403/30 | AA25: 45403 | AB25: 45409 | AC25: 45431 | AD25: 45444 | AE25: 45456 | AF25: 45472 | AG25: 45487 | AH25: 45494 | AI25: =AH25-V25 -> 161
A26: 16 | B26: 卒業 | C26: 0 | D26: 211 | E26: 0 | F26: 138 | G26: 64 | H26: あいざわくみこ | I26: okumi_mind | J26: https://www.notion.so/A-49f636e8bc784058b509202e308d986d?pvs=4 | K26: ふみや | L26: A組 | M26: ふみや | N26: 45328 | O26: 2月中旬 | P26: 45328 | R26: =W26 -> 45351 | S26: =R26+180 -> 45531 | T26: 清原三和子 | U26: 3 | V26: 45337 | W26: 45351 | X26: 45353 | Y26: 45372 | Z26: 45384 | AA26: 2024/0416 | AB26: 45412 | AC26: 45429 | AD26: 45440 | AE26: 45454 | AF26: 45467 | AG26: 45481 | AH26: 45496 | AI26: =AH26-V26 -> 159
A27: 17 | B27: 卒業 | C27: 0 | D27: 0 | E27: 0 | F27: 78 | G27: =F27-E27 -> 78 | H27: よこやまあいと | I27: satousanni_kokuhaku | J27: https://www.notion.so/B-53dabe8f44d94a4cb15a265041355304?pvs=4 | K27: ふみや | L27: B組 | M27: ふみや | N27: 45330 | O27: 2月中旬 | P27: 45330 | R27: =W27 -> 45360 | S27: =R27+180 -> 45540 | T27: 福田康裕 | U27: 1 | V27: 45335 | W27: 45360 | X27: 45381 | Y27: 45423 | Z27: 45445 | AA27: 45459 | AB27: 45473 | AC27: 45487 | AD27: 45508 | AE27: 45522 | AF27: 45536 | AG27: 45550 | AH27: 45560 | AI27: =AH27-V27 -> 225
A28: 18 | B28: 卒業 | C28: 0 | D28: 0 | E28: 0 | F28: 14 | G28: =F28-E28 -> 14 | H28: ふちがみあや | I28: aya_zubora | J28: https://www.notion.so/c7b88ab6a5674a1cb0260e9c208c019a | K28: ふみや | L28: B組 | M28: ふみや | N28: 45330 | O28: 2月中旬 | P28: 45330 | R28: =W28 -> 45350 | S28: =R28+180 -> 45530 | T28: 山見阪佳子 | U28: 2 | V28: 45336 | W28: 45350 | X28: 45366 | Y28: 45379 | Z28: 45397 | AA28: 45413 | AB28: 45441 | AC28: 45455 | AD28: 45468 | AE28: 45480 | AF28: 45495 | AG28: 45510 | AH28: 45525 | AI28: =AH28-V28 -> 189
A29: 19 | B29: 卒業 | C29: 0 | D29: 0 | E29: 154 | F29: 166 | H29: おおにしちかこ | I29: ginza_arch | J29: https://www.notion.so/J-87189eeb81284fd2af9b7cedea12687b?pvs=4 | K29: ソウタ | L29: J組 | M29: ハム | N29: 45347 | O29: 3月上旬〜中旬 | P29: 45348 | R29: =W29 -> 45412 | S29: =R29+180 -> 45592 | T29: 須見浩人 | U29: 1 | V29: 45353 | W29: 45412 | X29: 45435 | Y29: 45461 | Z29: 45481 | AA29: 45495 | AB29: 45505 | AC29: 45519 | AD29: 45543 | AE29: 45561 | AF29: 45575 | AG29: 45613 | AH29: 45630 | AI29: =AH29-V29 -> 277
A30: 20 | B30: 卒業 | C30: 1 | D30: 212 | E30: 0 | F30: 37 | H30: すだはるき | I30: haru_room100 | J30: https://www.notion.so/E-8f23d32f1f464421991d9ed8f6f8752d?pvs=4 | K30: 村松 | L30: E組 | M30: 村松 | N30: 45385 | O30: 4月下旬 | P30: 45385 | R30: =W30 -> 45414 | S30: =R30+180 -> 45594 | T30: 須見浩人 | U30: 2 | V30: 45402 | W30: 45414 | X30: 45443 | Y30: 45456 | Z30: 45477 | AA30: 45491 | AB30: 45513 | AC30: 45527 | AD30: 45541 | AE30: 45556 | AF30: 45572 | AG30: 45587 | AH30: 45602 | AI30: =AH30-V30 -> 200
A31: 21 | B31: 卒業 | C31: 0 | D31: 532 | E31: 0 | F31: 86 | H31: かしはらせつみ | I31: sena_bilife | J31: https://www.notion.so/L-b1b7515bcbb645c391931bdc154d8154?pvs=4 | K31: ソウタ | L31: L組 | M31: 村松 | N31: 45392 | O31: 4月下旬 | P31: 45392 | R31: =W31 -> 45406 | S31: =R31+180 -> 45586 | T31: 宮田友理 | U31: 4 | V31: 45398 | W31: 45406 | X31: 45420 | Y31: 45434 | Z31: 45455 | AA31: 45462 | AB31: 45485 | AC31: 45491 | AD31: 45505 | AE31: 45520 | AF31: 45532 | AG31: 45553 | AH31: 音信不通 | AI31: =AH31-V31 -> #VALUE!
A32: 22 | B32: 卒業 | C32: 1 | D32: 529 | E32: 0 | F32: 193 | H32: ながおあみり | I32: amiri_instastory | J32: https://www.notion.so/f-0cccca78988d43189901752f176bbefb | K32: 村松 | L32: F組 | M32: 村松 | N32: 45409 | O32: 5月中旬 | P32: 45410 | R32: =W32 -> 45435 | S32: =R32+180 -> 45615 | T32: 野村佑佳 | U32: 5 | V32: 45420 | W32: 45435 | X32: 45463 | Y32: 45477 | Z32: 45491 | AA32: 45512 | AB32: 45525 | AC32: 45540 | AD32: 45554 | AE32: 45568 | AF32: 45582 | AG32: 45602 | AH32: 45625 | AI32: =AH32-V32 -> 205
A33: 23 | B33: 卒業 | C33: 1 | D33: 422 | E33: 0 | F33: 76 | H33: こばやしはるか | I33: elu_excel.teiji | J33: https://www.instagram.com/elu_excel.teiji?utm_source=ig_web_button_share_sheet&igsh=ZDNlZDc0MzIxNw== | K33: 村松 | L33: F組 | M33: 村松 | N33: 45411 | O33: 5月中旬 | P33: 45414 | R33: =W33 -> 45449 | S33: =R33+180 -> 45629 | T33: 清原三和子 | U33: 4 | V33: 45423 | W33: 45449 | X33: 45463 | Y33: 45477 | Z33: 45491 | AA33: 45506 | AB33: 45526 | AC33: 45539 | AD33: 45554 | AE33: 45568 | AF33: 45580 | AG33: 45608 | AH33: 45625 | AI33: =AH33-V33 -> 202
A34: 24 | B34: 音不 | C34: 0 | D34: 0 | E34: 0 | H34: じょうどじゆうき | I34: じょうどじゆうき | K34: けいいち | L34: C組 | M34: けいいち | N34: 45429 | O34: 6月上旬 | P34: 45429 | R34: =W34 -> 45459 | S34: =R34+180 -> 45639 | T34: 福田康裕 | U34: 2 | V34: 45436 | W34: 45459 | X34: 45511 | AI34: =AH34-V34 -> -45436
A35: 25 | B35: 例外 | C35: 0 | D35: 0 | E35: 0 | H35: たなかゆりか | I35: たなかゆりか | K35: けいいち | L35: C組 | M35: けいいち | N35: 45430 | O35: 6月上旬 | P35: 45433 | R35: =W35 -> 45437 | S35: =R35+180 -> 45617 | T35: 清原三和子 | U35: 5 | V35: 45437 | W35: 45437 | AI35: =AH35-V35 -> -45437
A36: 26 | B36: 卒業 | C36: 0 | D36: 296 | E36: 0 | F36: 15 | H36: かわしま あらし | I36: fuui_guitar | J36: https://www.notion.so/_-G-8a956a5fe49943a582abe0647e358088?pvs=4 | K36: 村松 | L36: G組 | M36: 村松 | N36: 45434 | O36: 6月上旬 | P36: 45435 | R36: =W36 -> 45454 | S36: =R36+180 -> 45634 | T36: 森本風花 | U36: 3 | V36: 45441 | W36: 45454 | X36: 45469 | Y36: 45483 | Z36: 45496 | AA36: 45509 | AB36: 45525 | AC36: 45539 | AD36: 45553 | AE36: 45567 | AF36: 45581 | AG36: 45595 | AH36: 45623 | AI36: =AH36-V36 -> 182
A37: 27 | B37: 音不 | C37: 0 | D37: 0 | E37: 0 | H37: せきおかまさき | I37: せきおかまさき | J37: https://www.instagram.com/maxa.san1012?utm_source=ig_web_button_share_sheet&igsh=ZDNlZDc0MzIxNw== | K37: ふみや | L37: C組 | M37: ふみや | N37: 45438 | O37: 6月上旬 | P37: 45439 | R37: =W37 -> 45445 | S37: =R37+180 -> 45625 | T37: 福田康裕 | U37: 3 | V37: 45445 | W37: 45445 | AI37: =AH37-V37 -> -45445
A38: 28 | B38: 卒業 | C38: 0 | D38: 201 | E38: 0 | F38: 1 | H38: しらどうさき | I38: shirasaki_happylife | J38: https://www.notion.so/H-e9118b5dfb1f457190e1445e8dd95a10?pvs=4 | K38: 村松 | L38: H組 | M38: ゆり | N38: 45440 | O38: 45526 | P38: 45511 | R38: =W38 -> 45527 | S38: =R38+180 -> 45707 | T38: 宮田友理 | U38: 6 | V38: 45517 | W38: 45527 | X38: 45539 | Y38: 45568 | Z38: 45582 | AA38: 45596 | AB38: 45610 | AC38: 45625 | AD38: 45638 | AE38: 45653 | AF38: 45670 | AG38: 45680 | AH38: 45702 | AI38: =AH38-V38 -> 185
A39: 29 | B39: 卒業 | C39: 1 | D39: 443 | E39: 0 | F39: 79 | H39: まさきちさと | I39: hachi.footcare | J39: https://www.notion.so/C-bea817e079364bfca66194d09a437660?pvs=4 | K39: ふみや | L39: C組 | M39: ふみや | N39: 45440 | O39: 6月上旬 | P39: 45441 | R39: =W39 -> 45463 | S39: =R39+180 -> 45643 | T39: 宮田友理 | U39: 5 | V39: 45447 | W39: 45463 | X39: 45481 | Y39: 45495 | Z39: 45511 | AA39: 45526 | AB39: 45540 | AC39: 45554 | AD39: 45569 | AE39: 45593 | AF39: 45610 | AG39: 45622 | AH39: 45636 | AI39: =AH39-V39 -> 189
A40: 30 | B40: 卒業 | C40: 0 | D40: 301 | E40: 0 | F40: 110 | G40: 9 | H40: みよしゆうき | I40: yupi_nariagaru | J40: https://www.instagram.com/yupi_nariagaru?utm_source=ig_web_button_share_sheet&igsh=ZDNlZDc0MzIxNw== | K40: ふみや | L40: C組 | M40: ふみや | N40: 45441 | O40: 6月上旬 | P40: 45442 | R40: =W40 -> 45457 | S40: =R40+180 -> 45637 | T40: 清原三和子 | U40: 6 | V40: 45449 | W40: 45457 | X40: 45468 | Y40: 45481 | Z40: 45498 | AA40: 45511 | AB40: 45525 | AC40: 45537 | AD40: 45553 | AE40: 45582 | AF40: 45593 | AG40: 45610 | AH40: 45624 | AI40: =AH40-V40 -> 175
...

Sheet 目標値集計シート
C1: 生徒名 | D1: 在学・卒業合計 | E1: 在学中 | F1: 卒業生 | G1: 万垢達成 | H1: 期間中万垢 | I1: 卒業後万垢 | J1: 音信不通 | K1: 例外 | L1: クーリングオフ | S1: 目標値メモ | T1: アクション数評価 全体平均0.0pt以上（全体のアクション数が、300アクション以上） 投稿数評価 全体平均0.0pt以上（全体の卒業時投稿数平均が、60投稿以上）
C2: コミットプラン契約者数 | D2: =COUNTA('セッション実施状況管理'!H11:H663)-L2-J2-K2 -> 242 | E2: =COUNTIFS(C19:C437, "<>", I19:I437, "在学中") -> 158 | F2: =COUNTIFS(C19:C437, "<>", I19:I437, "卒業") -> 82 | G2: =IFERROR(__xludf.DUMMYFUNCTION("COUNTA( FILTER( C:C, COUNTIFS( 'セッション実施状況管理'!H:H, C:C, 'セッション実施状況管理'!C:C, "">=1"" )>0 ) )"),28.0) -> 28 | H2: =IFERROR(__xludf.DUMMYFUNCTION("COUNTA( FILTER( C:C, COUNTIFS( 'セッション実施状況管理'!H:H, C:C, 'セッション実施状況管理'!C:C, 1 )>0 ) )"),22.0) -> 22 | I2: =IFERROR(__xludf.DUMMYFUNCTION("COUNTA( FILTER( C:C, COUNTIFS( 'セッション実施状況管理'!H:H, C:C, 'セッション実施状況管理'!C:C, 2 )>0 ) )"),6.0) -> 6 | J2: =COUNTIFS(C19:C437, "<>", I19:I437, "音不") -> 10 | K2: =COUNTIFS(C19:C437, "<>", I19:I437, "例外") -> 6 | L2: =COUNTIFS(C19:C437, "<>", I19:I437, "クーリングオフ") -> 6
D3: 1 | E3: =E2/$D$2*100 -> 65.289256 | F3: =F2/$D$2*100 -> 33.884298 | G3: =G2/D2*100 -> 11.570248 | H3: =H2/D2*100 -> 9.0909091 | I3: =I2/D2*100 -> 2.4793388 | J3: =J2/$D$2*100 -> 4.1322314 | K3: =K2/$D$2*100 -> 2.4793388 | L3: =L2/$D$2*100 -> 2.4793388
F4: ⇧投稿数 | G4: ⇧投稿数
T8: =IFERROR(__xludf.DUMMYFUNCTION("AVERAGE( FILTER( T63:T200, ($I$63:$I$200=""在学中"") * ($S$63:$S$200=0) * (T63:T200<>"""") ) )"),"#DIV/0!") -> #DIV/0! | U8: =IFERROR(__xludf.DUMMYFUNCTION("AVERAGE( FILTER( U63:U200, ($I$63:$I$200=""在学中"") * ($S$63:$S$200=1) * (U63:U200<>"""") ) )"),"#N/A") -> #N/A | V8: =IFERROR(__xludf.DUMMYFUNCTION("AVERAGE( FILTER( V63:V200, ($I$63:$I$200=""在学中"") * ($S$63:$S$200=2) * (V63:V200<>"""") ) )"),134.0) -> 134 | W8: =IFERROR(__xludf.DUMMYFUNCTION("AVERAGE( FILTER( W63:W200, ($I$63:$I$200=""在学中"") * ($S$63:$S$200=3) * (W63:W200<>"""") ) )"),73.33333333333333) -> 73.333333 | X8: =IFERROR(__xludf.DUMMYFUNCTION("AVERAGE( FILTER( X63:X200, ($I$63:$I$200=""在学中"") * ($S$63:$S$200=4) * (X63:X200<>"""") ) )"),"#DIV/0!") -> #DIV/0! | Y8: =IFERROR(__xludf.DUMMYFUNCTION("AVERAGE( FILTER( Y63:Y200, ($I$63:$I$200=""在学中"") * ($S$63:$S$200=5) * (Y63:Y200<>"""") ) )"),"#DIV/0!") -> #DIV/0! | Z8: =IFERROR(__xludf.DUMMYFUNCTION("AVERAGE( FILTER( Z63:Z200, ($I$63:$I$200=""在学中"") * ($S$63:$S$200=6) * (Z63:Z200<>"""") ) )"),"#DIV/0!") -> #DIV/0!
F9: 120メンバー目標達成率(599) | P9: =IF(P16=0, "", P10 / P16 * 100) -> 46.432944 | Q9: =IF(Q16=0, "", Q10 / Q16 * 100) -> 68.555688 | R9: =IF(R16=0, "", R10 / R16 * 100) -> 81.062469 | T9: =IF(T16=0, "", T10 / T16 * 100) -> 72.579365 | U9: =IF(U16=0, "", U10 / U16 * 100) -> 85.044179 | V9: =IF(V16=0, "", V10 / V16 * 100) -> 82.637363 | W9: =IF(W16=0, "", W10 / W16 * 100) -> 73.855311 | X9: =IF(X16=0, "", X10 / X16 * 100) -> 62.474562 | Y9: =IF(Y16=0, "", Y10 / Y16 * 100) -> 61.538462 | Z9: =IF(Z16=0, "", Z10 / Z16 * 100) -> 102.82486
F10: 平均アクション数（120メンバーのみ） | J10: =IFERROR(__xludf.DUMMYFUNCTION("AVERAGE(FILTER(J63:J200, ($I$63:$I$200=""在学中"") * (J63:J200<>"""")))"),0.0) -> 0 | K10: =IFERROR(__xludf.DUMMYFUNCTION("AVERAGE(FILTER(K63:K200, ($I$63:$I$200=""在学中"") * (K63:K200<>"""")))"),0.8) -> 0.8 | L10: =IFERROR(__xludf.DUMMYFUNCTION("AVERAGE(FILTER(L63:L200, ($I$63:$I$200=""在学中"") * (L63:L200<>"""")))"),27.547169811320753) -> 27.54717 | M10: =IFERROR(__xludf.DUMMYFUNCTION("AVERAGE(FILTER(M63:M200, ($I$63:$I$200=""在学中"") * (M63:M200<>"""")))"),0.4) -> 0.4 | N10: =IFERROR(__xludf.DUMMYFUNCTION("AVERAGE(FILTER(N63:N200, ($I$63:$I$200=""在学中"") * (N63:N200<>"""")))"),1.1866666666666668) -> 1.1866667 | O10: =IFERROR(__xludf.DUMMYFUNCTION("AVERAGE(FILTER(O63:O200, ($I$63:$I$200=""在学中"") * (O63:O200<>"""")))"),-0.41333333333333333) -> -0.41333333 | P10: =IFERROR(__xludf.DUMMYFUNCTION("AVERAGE(FILTER(P63:P200, ($I$63:$I$200=""在学中"") * (P63:P200<>"""")))"),278.1333333333333) -> 278.13333 | Q10: =IFERROR(__xludf.DUMMYFUNCTION("AVERAGE(FILTER(Q63:Q200, ($I$63:$I$200=""在学中"") * (Q63:Q200<>"""")))"),410.6485714285715) -> 410.64857 | R10: =IFERROR(__xludf.DUMMYFUNCTION("AVERAGE(FILTER(R63:R200, ($I$63:$I$200=""在学中"") * (R63:R200<>"""")))"),69.36631274131274) -> 69.366313 | T10: =IFERROR(__xludf.DUMMYFUNCTION("AVERAGE(FILTER(T63:T200, ($I$63:$I$200=""在学中"") * (T63:T200<>"""")))"),52.25714285714286) -> 52.257143 | U10: =IFERROR(__xludf.DUMMYFUNCTION("AVERAGE(FILTER(U63:U200, ($I$63:$I$200=""在学中"") * (U63:U200<>"""")))"),88.44594594594595) -> 88.445946 | V10: =IFERROR(__xludf.DUMMYFUNCTION("AVERAGE(FILTER(V63:V200, ($I$63:$I$200=""在学中"") * (V63:V200<>"""")))"),75.2) -> 75.2 | W10: =IFERROR(__xludf.DUMMYFUNCTION("AVERAGE(FILTER(W63:W200, ($I$63:$I$200=""在学中"") * (W63:W200<>"""")))"),67.20833333333333) -> 67.208333 | X10: =IFERROR(__xludf.DUMMYFUNCTION("AVERAGE(FILTER(X63:X200, ($I$63:$I$200=""在学中"") * (X63:X200<>"""")))"),56.851851851851855) -> 56.851852 | Y10: =IFERROR(__xludf.DUMMYFUNCTION("AVERAGE(FILTER(Y63:Y200, ($I$63:$I$200=""在学中"") * (Y63:Y200<>"""")))"),56.0) -> 56 | Z10: =IFERROR(__xludf.DUMMYFUNCTION("AVERAGE(FILTER(Z63:Z200, ($I$63:$I$200=""在学中"") * (Z63:Z200<>"""")))"),60.666666666666664) -> 60.666667
F11: 120-在学生 差 | J11: =J10-J12 -> 0 | K11: =K10-K12 -> 0 | L11: =L10-L12 -> 0 | M11: =M10-M12 -> 0.0052631579 | N11: =N10-N12 -> -0.010701754 | O11: =O10-O12 -> 0.020877193 | P11: =P10-P12 -> 0.64649123 | Q11: =Q10-Q12 -> -0.62304511 | R11: =R10-R12 -> -0.092893608 | T11: =T10-T12 -> 0.7360161 | U11: =U10-U12 -> -0.90072072 | V11: =V10-V12 -> 0.030985915 | W11: =W10-W12 -> 0 | X11: =X10-X12 -> 0 | Y11: =Y10-Y12 -> 0 | Z11: =Z10-Z12 -> 0
F12: 平均アクション数（在学生全体） | J12: =IFERROR(__xludf.DUMMYFUNCTION("AVERAGE(FILTER(J40:J201, ($I40:$I$201=""在学中"") * (J40:J201<>"""")))"),0.0) -> 0 | K12: =IFERROR(__xludf.DUMMYFUNCTION("AVERAGE(FILTER(K40:K201, ($I40:$I$201=""在学中"") * (K40:K201<>"""")))"),0.8) -> 0.8 | L12: =IFERROR(__xludf.DUMMYFUNCTION("AVERAGE(FILTER(L40:L201, ($I40:$I$201=""在学中"") * (L40:L201<>"""")))"),27.547169811320753) -> 27.54717 | M12: =IFERROR(__xludf.DUMMYFUNCTION("AVERAGE(FILTER(M40:M201, ($I40:$I$201=""在学中"") * (M40:M201<>"""")))"),0.39473684210526316) -> 0.39473684 | N12: =IFERROR(__xludf.DUMMYFUNCTION("AVERAGE(FILTER(N40:N201, ($I40:$I$201=""在学中"") * (N40:N201<>"""")))"),1.1973684210526316) -> 1.1973684 | O12: =IFERROR(__xludf.DUMMYFUNCTION("AVERAGE(FILTER(O40:O201, ($I40:$I$201=""在学中"") * (O40:O201<>"""")))"),-0.4342105263157895) -> -0.43421053 | P12: =IFERROR(__xludf.DUMMYFUNCTION("AVERAGE(FILTER(P40:P201, ($I40:$I$201=""在学中"") * (P40:P201<>"""")))"),277.4868421052632) -> 277.48684 | Q12: =IFERROR(__xludf.DUMMYFUNCTION("AVERAGE(FILTER(Q40:Q201, ($I40:$I$201=""在学中"") * (Q40:Q201<>"""")))"),411.2716165413534) -> 411.27162 | R12: =IFERROR(__xludf.DUMMYFUNCTION("AVERAGE(FILTER(R40:R201, ($I40:$I$201=""在学中"") * (R40:R201<>"""")))"),69.45920634920635) -> 69.459206 | T12: =IFERROR(__xludf.DUMMYFUNCTION("AVERAGE(FILTER(T40:T201, ($I40:$I$201=""在学中"") * (T40:T201<>"""")))"),51.521126760563384) -> 51.521127 | U12: =IFERROR(__xludf.DUMMYFUNCTION("AVERAGE(FILTER(U40:U201, ($I40:$I$201=""在学中"") * (U40:U201<>"""")))"),89.34666666666666) -> 89.346667 | V12: =IFERROR(__xludf.DUMMYFUNCTION("AVERAGE(FILTER(V40:V201, ($I40:$I$201=""在学中"") * (V40:V201<>"""")))"),75.16901408450704) -> 75.169014 | W12: =IFERROR(__xludf.DUMMYFUNCTION("AVERAGE(FILTER(W40:W201, ($I40:$I$201=""在学中"") * (W40:W201<>"""")))"),67.20833333333333) -> 67.208333 | X12: =IFERROR(__xludf.DUMMYFUNCTION("AVERAGE(FILTER(X40:X201, ($I40:$I$201=""在学中"") * (X40:X201<>"""")))"),56.851851851851855) -> 56.851852 | Y12: =IFERROR(__xludf.DUMMYFUNCTION("AVERAGE(FILTER(Y40:Y201, ($I40:$I$201=""在学中"") * (Y40:Y201<>"""")))"),56.0) -> 56 | Z12: =IFERROR(__xludf.DUMMYFUNCTION("AVERAGE(FILTER(Z40:Z201, ($I40:$I$201=""在学中"") * (Z40:Z201<>"""")))"),60.666666666666664) -> 60.666667
F13: 平均アクション数（120投稿以外） | J13: =IFERROR(__xludf.DUMMYFUNCTION("AVERAGE(FILTER(J19:J39, (($I19:$I$39=""在学中"") + ($I19:$I$39=""卒業"")) * (J19:J39<>"""")))"),0.0) -> 0 | K13: =IFERROR(__xludf.DUMMYFUNCTION("AVERAGE(FILTER(K19:K39, (($I19:$I$39=""在学中"") + ($I19:$I$39=""卒業"")) * (K19:K39<>"""")))"),0.4) -> 0.4 | L13: =IFERROR(__xludf.DUMMYFUNCTION("AVERAGE(FILTER(L19:L39, (($I19:$I$39=""在学中"") + ($I19:$I$39=""卒業"")) * (L19:L39<>"""")))"),48.45) -> 48.45 | M13: =IFERROR(__xludf.DUMMYFUNCTION("AVERAGE(FILTER(M19:M39, (($I19:$I$39=""在学中"") + ($I19:$I$39=""卒業"")) * (M19:M39<>"""")))"),-1.0) -> -1 | N13: =IFERROR(__xludf.DUMMYFUNCTION("AVERAGE(FILTER(N19:N39, (($I19:$I$39=""在学中"") + ($I19:$I$39=""卒業"")) * (N19:N39<>"""")))"),0.6) -> 0.6 | O13: =IFERROR(__xludf.DUMMYFUNCTION("AVERAGE(FILTER(O19:O39, (($I19:$I$39=""在学中"") + ($I19:$I$39=""卒業"")) * (O19:O39<>"""")))"),-0.55) -> -0.55 | P13: =IFERROR(__xludf.DUMMYFUNCTION("AVERAGE(FILTER(P19:P39, (($I19:$I$39=""在学中"") + ($I19:$I$39=""卒業"")) * (P19:P39<>"""")))"),256.5) -> 256.5 | Q13: =IFERROR(__xludf.DUMMYFUNCTION("AVERAGE(FILTER(Q19:Q39, (($I19:$I$39=""在学中"") + ($I19:$I$39=""卒業"")) * (Q19:Q39<>"""")))"),365.5664285714286) -> 365.56643 | R13: =IFERROR(__xludf.DUMMYFUNCTION("AVERAGE(FILTER(R19:R39, (($I19:$I$39=""在学中"") + ($I19:$I$39=""卒業"")) * (R19:R39<>"""")))"),64.13446115288221) -> 64.134461 | T13: =IFERROR(__xludf.DUMMYFUNCTION("AVERAGE(FILTER(T19:T39, (($I19:$I$39=""在学中"") + ($I19:$I$39=""卒業"")) * (T19:T39<>"""")))"),1.6666666666666667) -> 1.6666667 | U13: =IFERROR(__xludf.DUMMYFUNCTION("AVERAGE(FILTER(U19:U39, (($I19:$I$39=""在学中"") + ($I19:$I$39=""卒業"")) * (U19:U39<>"""")))"),50.666666666666664) -> 50.666667 | V13: =IFERROR(__xludf.DUMMYFUNCTION("AVERAGE(FILTER(V19:V39, (($I19:$I$39=""在学中"") + ($I19:$I$39=""卒業"")) * (V19:V39<>"""")))"),41.77777777777778) -> 41.777778 | W13: =IFERROR(__xludf.DUMMYFUNCTION("AVERAGE(FILTER(W19:W39, (($I19:$I$39=""在学中"") + ($I19:$I$39=""卒業"")) * (W19:W39<>"""")))"),68.3076923076923) -> 68.307692 | X13: =IFERROR(__xludf.DUMMYFUNCTION("AVERAGE(FILTER(X19:X39, (($I19:$I$39=""在学中"") + ($I19:$I$39=""卒業"")) * (X19:X39<>"""")))"),74.22222222222223) -> 74.222222 | Y13: =IFERROR(__xludf.DUMMYFUNCTION("AVERAGE(FILTER(Y19:Y39, (($I19:$I$39=""在学中"") + ($I19:$I$39=""卒業"")) * (Y19:Y39<>"""")))"),80.57894736842105) -> 80.578947 | Z13: =IFERROR(__xludf.DUMMYFUNCTION("AVERAGE(FILTER(Z19:Z39, (($I19:$I$39=""在学中"") + ($I19:$I$39=""卒業"")) * (Z19:Z39<>"""")))"),36.31578947368421) -> 36.315789
U14: =IFERROR(__xludf.DUMMYFUNCTION("COUNT( FILTER( U63:U200, ($I$63:$I$200=""在学中"") * (U63:U200<>"""") ) )"),74.0) -> 74 | V14: =IFERROR(__xludf.DUMMYFUNCTION("COUNT( FILTER( V63:V200, ($I$63:$I$200=""在学中"") * (V63:V200<>"""") ) )"),70.0) -> 70 | W14: =IFERROR(__xludf.DUMMYFUNCTION("COUNT( FILTER( W63:W200, ($I$63:$I$200=""在学中"") * (W63:W200<>"""") ) )"),48.0) -> 48 | X14: =IFERROR(__xludf.DUMMYFUNCTION("COUNT( FILTER( X63:X200, ($I$63:$I$200=""在学中"") * (X63:X200<>"""") ) )"),27.0) -> 27 | Y14: =IFERROR(__xludf.DUMMYFUNCTION("COUNT( FILTER( Y63:Y200, ($I$63:$I$200=""在学中"") * (Y63:Y200<>"""") ) )"),11.0) -> 11 | Z14: =IFERROR(__xludf.DUMMYFUNCTION("COUNT( FILTER( Z63:Z200, ($I$63:$I$200=""在学中"") * (Z63:Z200<>"""") ) )"),3.0) -> 3
F15: 累計 | T15: =SUM(T16) -> 72 | U15: =SUM(T15,U16) -> 176 | V15: =SUM(U15,V16) -> 267 | W15: =SUM(V15,W16) -> 358 | X15: =SUM(W15,X16) -> 449 | Y15: =SUM(X15,Y16) -> 540 | Z15: =SUM(Y15,Z16) -> 599
E16: =average(G16:M16) -> 54.75 | F16: 単月目標（599） | J16: 72 | K16: 72 | L16: 72 | M16: 3 | N16: 4 | O16: 4 | P16: 599 | Q16: 599 | R16: =AVERAGE(T16:Z16) -> 85.571429 | T16: 72 | U16: 104 | V16: 91 | W16: 91 | X16: 91 | Y16: 91 | Z16: 59
C17: 関数 | D17: 関数 | E17: 手動入力 | F17: 関数 | G17: 関数 | H17: ▼MAX13 | I17: 関数 | J17: 手動入力 | K17: 手動入力 | M17: 関数 | N17: 関数 | O17: 関数 | P17: 関数 | Q17: 関数 | R17: 関数 | T17: ▼NEWアクション数算出
B18: no. | D18: user ID | E18: アクションシート | F18: 担当コーチ | H18: セッション回数 | I18: 卒業在学 | J18: MVP | K18: 万垢・音不 | L18: 投稿数 | M18: 投稿評価 | N18: 予想アクション評価 | O18: 実績 アクション評価 | P18: 合計 | Q18: 予想合計アクションpt | R18: O列調整月間平均 | S18: 提出期間 | T18: 0ヶ月目 | U18: 1ヶ月目 | V18: 2ヶ月目 | W18: 3ヶ月目 | X18: 4ヶ月目 | Y18: 5ヶ月目 | Z18: 6ヶ月目 | AA18: 通常セッション | AB18: 入会からの経過月数 | AC18: 投稿カウント対象(1)
B19: 1 | C19: =vlookup(B19,'セッション実施状況管理'!$A:$U,8,false) -> おのまこと | D19: =vlookup(B19,'セッション実施状況管理'!$A:$I,9,false) -> koji_no_chie | E19: なし | F19: =vlookup(B19,'セッション実施状況管理'!$A:$U,20,false) -> 宮田友理 | G19: =vlookup(B19,'セッション実施状況管理'!$A:$U,20,false) -> 宮田友理 | H19: ='コーチング報酬管理'!G7 -> 6 | I19: =iferror(vlookup(B19,'セッション実施状況管理'!$A:$B,2,false),"") -> 例外 | J19: 0 | K19: 0 | L19: =VLOOKUP(B19,'新 月次投稿数'!$A:$N,13,false) -> 0 | M19: =IF(L19>=120, 3, IF(L19>=100, 2, IF(L19>=80, 1, IF(L19>=60, 0, IF(L19>=40, -1, IF(L19>=20, -2, -3)))))) -> -3 | N19: =IF(Q19>=540, 4, IF(Q19>=480, 3, IF(Q19>=420, 2, IF(Q19>=360, 1, IF(Q19>=300, 0, IF(Q19>=240, -1, -2)))))) -> -2 | O19: =IF(P19>=540, 4, IF(P19>=480, 3, IF(P19>=420, 2, IF(P19>=360, 1, IF(P19>=300, 0, IF(P19>=240, -1, -2)))))) -> -2 | P19: =sum(T19:Z19) -> 0 | Q19: 0 | R19: =iferror(P19/S19,"0") -> 0 | S19: =count(T19:Z19) -> 0 | T19: ー | U19: ー | V19: ー | W19: ー | X19: ー | Y19: ー | Z19: ー | AA19: =Vlookup(B19,'セッション実施状況管理'!$A:$R,17,false) -> - | AB19: =(YEAR(TODAY()) - YEAR($AA19)) * 12 + (MONTH(TODAY()) - MONTH($AA19)) -> #VALUE! | AC19: =IF( OR(AB19=3, AB19=4, AB19=5, AB19=6), "1", "2" ) -> #VALUE!
B20: 2 | C20: =vlookup(B20,'セッション実施状況管理'!$A:$U,8,false) -> ただゆうすけ | D20: =vlookup(B20,'セッション実施状況管理'!$A:$I,9,false) -> cya_kurashi | E20: https://docs.google.com/spreadsheets/d/1RQ1i_eyk31MMP-wjt5wEUlXzJWPRVCjqK3ZmtmiYJiY/edit?usp=sharing | F20: =vlookup(B20,'セッション実施状況管理'!$A:$U,20,false) -> 中村恵理 | G20: =vlookup(B20,'セッション実施状況管理'!$A:$U,20,false) -> 中村恵理 | H20: ='コーチング報酬管理'!G8 -> 13 | I20: =iferror(vlookup(B20,'セッション実施状況管理'!$A:$B,2,false),"") -> 卒業 | J20: 0 | K20: 2 | L20: =VLOOKUP(B20,'新 月次投稿数'!$A:$N,13,false) -> 89 | M20: =IF(L20>=120, 3, IF(L20>=100, 2, IF(L20>=80, 1, IF(L20>=60, 0, IF(L20>=40, -1, IF(L20>=20, -2, -3)))))) -> 1 | N20: =IF(Q20>=540, 4, IF(Q20>=480, 3, IF(Q20>=420, 2, IF(Q20>=360, 1, IF(Q20>=300, 0, IF(Q20>=240, -1, -2)))))) -> 4 | O20: =IF(P20>=540, 4, IF(P20>=480, 3, IF(P20>=420, 2, IF(P20>=360, 1, IF(P20>=300, 0, IF(P20>=240, -1, -2)))))) -> -1 | P20: =sum(T20:Z20) -> 289 | Q20: =R20*6 -> 867 | R20: =iferror(P20/S20,"0") -> 144.5 | S20: =count(T20:Z20) -> 2 | T20: ー | U20: ー | V20: ー | W20: ー | X20: ー | Y20: 190 | Z20: 99 | AA20: =Vlookup(B20,'セッション実施状況管理'!$A:$R,17,false) -> - | AB20: =(YEAR(TODAY()) - YEAR($AA20)) * 12 + (MONTH(TODAY()) - MONTH($AA20)) -> #VALUE! | AC20: =IF( OR(AB20=3, AB20=4, AB20=5, AB20=6), "1", "2" ) -> #VALUE!
B21: 3 | C21: =vlookup(B21,'セッション実施状況管理'!$A:$U,8,false) -> ふじたなな | D21: =vlookup(B21,'セッション実施状況管理'!$A:$I,9,false) -> ta_ma_diet | E21: https://docs.google.com/spreadsheets/d/13WYWfgJBL9cRnrDfXGMTMyu-O1Oo2N6x-99iOo9amV0/edit#gid=159884613 | F21: =vlookup(B21,'セッション実施状況管理'!$A:$U,20,false) -> 森本風花 | G21: =vlookup(B21,'セッション実施状況管理'!$A:$U,20,false) -> 森本風花 | H21: ='コーチング報酬管理'!G9 -> 13 | I21: =iferror(vlookup(B21,'セッション実施状況管理'!$A:$B,2,false),"") -> 卒業 | J21: 0 | K21: 0 | L21: =VLOOKUP(B21,'新 月次投稿数'!$A:$N,13,false) -> 0 | M21: =IF(L21>=120, 3, IF(L21>=100, 2, IF(L21>=80, 1, IF(L21>=60, 0, IF(L21>=40, -1, IF(L21>=20, -2, -3)))))) -> -3 | N21: =IF(Q21>=540, 4, IF(Q21>=480, 3, IF(Q21>=420, 2, IF(Q21>=360, 1, IF(Q21>=300, 0, IF(Q21>=240, -1, -2)))))) -> -2 | O21: =IF(P21>=540, 4, IF(P21>=480, 3, IF(P21>=420, 2, IF(P21>=360, 1, IF(P21>=300, 0, IF(P21>=240, -1, -2)))))) -> -2 | P21: =sum(T21:Z21) -> 78 | Q21: =R21*6 -> 156 | R21: =iferror(P21/S21,"0") -> 26 | S21: =count(T21:Z21) -> 3 | T21: ー | U21: ー | V21: ー | W21: ー | X21: 18 | Y21: 41 | Z21: 19 | AA21: =Vlookup(B21,'セッション実施状況管理'!$A:$R,17,false) | AB21: =(YEAR(TODAY()) - YEAR($AA21)) * 12 + (MONTH(TODAY()) - MONTH($AA21)) -> 1514 | AC21: =IF( OR(AB21=3, AB21=4, AB21=5, AB21=6), "1", "2" ) -> 2
B22: 4 | C22: =vlookup(B22,'セッション実施状況管理'!$A:$U,8,false) -> よしだむつみ | D22: =vlookup(B22,'セッション実施状況管理'!$A:$I,9,false) -> adhd_nao | E22: https://docs.google.com/spreadsheets/d/1P7lV1jvZjxbK1uZ7NM7uhW3LAsP0PYvQKrq7aPBsOk4/edit?usp=sharing | F22: =vlookup(B22,'セッション実施状況管理'!$A:$U,20,false) -> 野村佑佳 | G22: =vlookup(B22,'セッション実施状況管理'!$A:$U,20,false) -> 野村佑佳 | H22: ='コーチング報酬管理'!G10 -> 13 | I22: =iferror(vlookup(B22,'セッション実施状況管理'!$A:$B,2,false),"") -> 卒業 | J22: 0 | K22: 0 | L22: =VLOOKUP(B22,'新 月次投稿数'!$A:$N,13,false) -> 0 | M22: =IF(L22>=120, 3, IF(L22>=100, 2, IF(L22>=80, 1, IF(L22>=60, 0, IF(L22>=40, -1, IF(L22>=20, -2, -3)))))) -> -3 | N22: =IF(Q22>=540, 4, IF(Q22>=480, 3, IF(Q22>=420, 2, IF(Q22>=360, 1, IF(Q22>=300, 0, IF(Q22>=240, -1, -2)))))) -> -2 | O22: =IF(P22>=540, 4, IF(P22>=480, 3, IF(P22>=420, 2, IF(P22>=360, 1, IF(P22>=300, 0, IF(P22>=240, -1, -2)))))) -> -2 | P22: =sum(T22:Z22) -> 74 | Q22: =R22*6 -> 148 | R22: =iferror(P22/S22,"0") -> 24.666667 | S22: =count(T22:Z22) -> 3 | T22: ー | U22: ー | V22: ― | W22: ― | X22: 74 | Y22: 0 | Z22: 0 | AA22: =Vlookup(B22,'セッション実施状況管理'!$A:$R,17,false) | AB22: =(YEAR(TODAY()) - YEAR($AA22)) * 12 + (MONTH(TODAY()) - MONTH($AA22)) -> 1514 | AC22: =IF( OR(AB22=3, AB22=4, AB22=5, AB22=6), "1", "2" ) -> 2
B23: 5 | C23: =vlookup(B23,'セッション実施状況管理'!$A:$U,8,false) -> きたがわたかひろ | D23: =vlookup(B23,'セッション実施状況管理'!$A:$I,9,false) -> kcc_0113 | E23: https://docs.google.com/spreadsheets/d/1dDsldPC_LoIFAFPjNSBbpMJoKhvVhpWWe__BpOst8ig/edit | F23: =vlookup(B23,'セッション実施状況管理'!$A:$U,20,false) -> 豊榮信江 | G23: =vlookup(B23,'セッション実施状況管理'!$A:$U,20,false) -> 豊榮信江 | H23: ='コーチング報酬管理'!G11 -> 12 | I23: =iferror(vlookup(B23,'セッション実施状況管理'!$A:$B,2,false),"") -> 卒業 | J23: 0 | K23: 0 | L23: =VLOOKUP(B23,'新 月次投稿数'!$A:$N,13,false) -> 0 | M23: =IF(L23>=120, 3, IF(L23>=100, 2, IF(L23>=80, 1, IF(L23>=60, 0, IF(L23>=40, -1, IF(L23>=20, -2, -3)))))) -> -3 | N23: =IF(Q23>=540, 4, IF(Q23>=480, 3, IF(Q23>=420, 2, IF(Q23>=360, 1, IF(Q23>=300, 0, IF(Q23>=240, -1, -2)))))) -> -2 | O23: =IF(P23>=540, 4, IF(P23>=480, 3, IF(P23>=420, 2, IF(P23>=360, 1, IF(P23>=300, 0, IF(P23>=240, -1, -2)))))) -> -2 | P23: =sum(T23:Z23) -> 136 | Q23: =R23*6 -> 204 | R23: =iferror(P23/S23,"0") -> 34 | S23: =count(T23:Z23) -> 4 | T23: ー | U23: ー | V23: ー | W23: 3 | X23: 73 | Y23: 44 | Z23: 16 | AA23: =Vlookup(B23,'セッション実施状況管理'!$A:$R,17,false) | AB23: =(YEAR(TODAY()) - YEAR($AA23)) * 12 + (MONTH(TODAY()) - MONTH($AA23)) -> 1514 | AC23: =IF( OR(AB23=3, AB23=4, AB23=5, AB23=6), "1", "2" ) -> 2
B24: 6 | C24: =vlookup(B24,'セッション実施状況管理'!$A:$U,8,false) -> ありやまゆうな | D24: =vlookup(B24,'セッション実施状況管理'!$A:$I,9,false) -> uni_beer_ | E24: https://docs.google.com/spreadsheets/d/1VF6-P-SWrjPNTkdevk6pBPF7_eKqo9Y4HqFzaHa75IY/edit?usp=sharing | F24: =vlookup(B24,'セッション実施状況管理'!$A:$U,20,false) -> 野村佑佳 | G24: =vlookup(B24,'セッション実施状況管理'!$A:$U,20,false) -> 野村佑佳 | H24: ='コーチング報酬管理'!G13 -> 13 | I24: =iferror(vlookup(B24,'セッション実施状況管理'!$A:$B,2,false),"") -> 卒業 | J24: 0 | K24: 2 | L24: =VLOOKUP(B24,'新 月次投稿数'!$A:$N,13,false) -> 102 | M24: =IF(L24>=120, 3, IF(L24>=100, 2, IF(L24>=80, 1, IF(L24>=60, 0, IF(L24>=40, -1, IF(L24>=20, -2, -3)))))) -> 2 | N24: =IF(Q24>=540, 4, IF(Q24>=480, 3, IF(Q24>=420, 2, IF(Q24>=360, 1, IF(Q24>=300, 0, IF(Q24>=240, -1, -2)))))) -> 4 | O24: =IF(P24>=540, 4, IF(P24>=480, 3, IF(P24>=420, 2, IF(P24>=360, 1, IF(P24>=300, 0, IF(P24>=240, -1, -2)))))) -> 4 | P24: =sum(T24:Z24) -> 829 | Q24: =R24*6 -> 829 | R24: =iferror(P24/S24,"0") -> 138.16667 | S24: =count(T24:Z24) -> 6 | T24: ー | U24: 195 | V24: 186 | W24: 189 | X24: 101 | Y24: 95 | Z24: 63 | AA24: =Vlookup(B24,'セッション実施状況管理'!$A:$R,17,false) | AB24: =(YEAR(TODAY()) - YEAR($AA24)) * 12 + (MONTH(TODAY()) - MONTH($AA24)) -> 1514 | AC24: =IF( OR(AB24=3, AB24=4, AB24=5, AB24=6), "1", "2" ) -> 2
B25: 7 | C25: =vlookup(B25,'セッション実施状況管理'!$A:$U,8,false) -> たけにしゆかり | D25: =vlookup(B25,'セッション実施状況管理'!$A:$I,9,false) -> yukari_dekirumon | E25: https://docs.google.com/spreadsheets/d/1FDgWv1TaU7NONEzy8isYhtlzxGj8bpfooK0xi56QQQI/edit?usp=sharing | F25: =vlookup(B25,'セッション実施状況管理'!$A:$U,20,false) -> 宮田友理 | G25: =vlookup(B25,'セッション実施状況管理'!$A:$U,20,false) -> 宮田友理 | H25: ='コーチング報酬管理'!G14 -> 13 | I25: =iferror(vlookup(B25,'セッション実施状況管理'!$A:$B,2,false),"") -> 卒業 | J25: 0 | K25: 0 | L25: =VLOOKUP(B25,'新 月次投稿数'!$A:$N,13,false) -> 6 | M25: =IF(L25>=120, 3, IF(L25>=100, 2, IF(L25>=80, 1, IF(L25>=60, 0, IF(L25>=40, -1, IF(L25>=20, -2, -3)))))) -> -3 | N25: =IF(Q25>=540, 4, IF(Q25>=480, 3, IF(Q25>=420, 2, IF(Q25>=360, 1, IF(Q25>=300, 0, IF(Q25>=240, -1, -2)))))) -> -2 | O25: =IF(P25>=540, 4, IF(P25>=480, 3, IF(P25>=420, 2, IF(P25>=360, 1, IF(P25>=300, 0, IF(P25>=240, -1, -2)))))) -> -2 | P25: =sum(T25:Z25) -> 18 | Q25: =R25*6 -> 18 | R25: =iferror(P25/S25,"0") -> 3 | S25: =count(T25:Z25) -> 6 | T25: ー | U25: 17 | V25: 1 | W25: 0 | X25: 0 | Y25: 0 | Z25: 0 | AA25: =Vlookup(B25,'セッション実施状況管理'!$A:$R,17,false) | AB25: =(YEAR(TODAY()) - YEAR($AA25)) * 12 + (MONTH(TODAY()) - MONTH($AA25)) -> 1514 | AC25: =IF( OR(AB25=3, AB25=4, AB25=5, AB25=6), "1", "2" ) -> 2
B26: 8 | C26: =vlookup(B26,'セッション実施状況管理'!$A:$U,8,false) -> くどうゆみこ | D26: =vlookup(B26,'セッション実施状況管理'!$A:$I,9,false) -> くどうゆみこ | E26: https://docs.google.com/spreadsheets/d/16gm19l8AK-WT0DiGdwsvCSYJyap52t5KdnlJ7ASvaSQ/edit?usp=sharing | F26: =vlookup(B26,'セッション実施状況管理'!$A:$U,20,false) -> 野村佑佳 | G26: =vlookup(B26,'セッション実施状況管理'!$A:$U,20,false) -> 野村佑佳 | H26: ='コーチング報酬管理'!G15 -> 13 | I26: =iferror(vlookup(B26,'セッション実施状況管理'!$A:$B,2,false),"") -> 卒業 | J26: 0 | K26: 0 | L26: =VLOOKUP(B26,'新 月次投稿数'!$A:$N,13,false) -> 45 | M26: =IF(L26>=120, 3, IF(L26>=100, 2, IF(L26>=80, 1, IF(L26>=60, 0, IF(L26>=40, -1, IF(L26>=20, -2, -3)))))) -> -1 | N26: =IF(Q26>=540, 4, IF(Q26>=480, 3, IF(Q26>=420, 2, IF(Q26>=360, 1, IF(Q26>=300, 0, IF(Q26>=240, -1, -2)))))) -> -2 | O26: =IF(P26>=540, 4, IF(P26>=480, 3, IF(P26>=420, 2, IF(P26>=360, 1, IF(P26>=300, 0, IF(P26>=240, -1, -2)))))) -> -2 | P26: =sum(T26:Z26) -> 0 | Q26: =R26*6 -> 0 | R26: =iferror(P26/S26,"0") -> 0 | S26: =count(T26:Z26) -> 0 | T26: ー | U26: ー | V26: ー | W26: ー | X26: ー | Y26: ー | Z26: ー | AA26: =Vlookup(B26,'セッション実施状況管理'!$A:$R,17,false) | AB26: =(YEAR(TODAY()) - YEAR($AA26)) * 12 + (MONTH(TODAY()) - MONTH($AA26)) -> 1514 | AC26: =IF( OR(AB26=3, AB26=4, AB26=5, AB26=6), "1", "2" ) -> 2
B27: 9 | C27: =vlookup(B27,'セッション実施状況管理'!$A:$U,8,false) -> たわらかずみ | D27: =vlookup(B27,'セッション実施状況管理'!$A:$I,9,false) -> negi_mamalife | E27: https://docs.google.com/spreadsheets/d/1VcZW6sZO5CzEjG-LGvBO6r1yQjJicqYLWUDbBD9Pw2E/edit | F27: =vlookup(B27,'セッション実施状況管理'!$A:$U,20,false) -> 中村恵理 | G27: =vlookup(B27,'セッション実施状況管理'!$A:$U,20,false) -> 中村恵理 | H27: ='コーチング報酬管理'!G16 -> 13 | I27: =iferror(vlookup(B27,'セッション実施状況管理'!$A:$B,2,false),"") -> 卒業 | J27: 0 | K27: 0 | L27: =VLOOKUP(B27,'新 月次投稿数'!$A:$N,13,false) -> 109 | M27: =IF(L27>=120, 3, IF(L27>=100, 2, IF(L27>=80, 1, IF(L27>=60, 0, IF(L27>=40, -1, IF(L27>=20, -2, -3)))))) -> 2 | N27: =IF(Q27>=540, 4, IF(Q27>=480, 3, IF(Q27>=420, 2, IF(Q27>=360, 1, IF(Q27>=300, 0, IF(Q27>=240, -1, -2)))))) -> 3 | O27: =IF(P27>=540, 4, IF(P27>=480, 3, IF(P27>=420, 2, IF(P27>=360, 1, IF(P27>=300, 0, IF(P27>=240, -1, -2)))))) -> -1 | P27: =sum(T27:Z27) -> 247 | Q27: =R27*6 -> 494 | R27: =iferror(P27/S27,"0") -> 82.333333 | S27: =count(T27:Z27) -> 3 | T27: ー | U27: ー | V27: ー | W27: ー | X27: 112 | Y27: 102 | Z27: 33 | AA27: =Vlookup(B27,'セッション実施状況管理'!$A:$R,17,false) | AB27: =(YEAR(TODAY()) - YEAR($AA27)) * 12 + (MONTH(TODAY()) - MONTH($AA27)) -> 1514 | AC27: =IF( OR(AB27=3, AB27=4, AB27=5, AB27=6), "1", "2" ) -> 2
B28: 10 | C28: =vlookup(B28,'セッション実施状況管理'!$A:$U,8,false) -> やまぐちしんいちろう | D28: =vlookup(B28,'セッション実施状況管理'!$A:$I,9,false) -> tewofuru_woodjewelry | E28: https://docs.google.com/spreadsheets/d/1HGYcq04YAsY7AfEQsu6pG2qTM6XEKBkaugZcBIDQ6MI/edit#gid=159884613 | F28: =vlookup(B28,'セッション実施状況管理'!$A:$U,20,false) -> 森本風花 | G28: =vlookup(B28,'セッション実施状況管理'!$A:$U,20,false) -> 森本風花 | H28: ='コーチング報酬管理'!G17 -> 13 | I28: =iferror(vlookup(B28,'セッション実施状況管理'!$A:$B,2,false),"") -> 卒業 | J28: 0 | K28: 0 | L28: =VLOOKUP(B28,'新 月次投稿数'!$A:$N,13,false) -> 128 | M28: =IF(L28>=120, 3, IF(L28>=100, 2, IF(L28>=80, 1, IF(L28>=60, 0, IF(L28>=40, -1, IF(L28>=20, -2, -3)))))) -> 3 | N28: =IF(Q28>=540, 4, IF(Q28>=480, 3, IF(Q28>=420, 2, IF(Q28>=360, 1, IF(Q28>=300, 0, IF(Q28>=240, -1, -2)))))) -> 4 | O28: =IF(P28>=540, 4, IF(P28>=480, 3, IF(P28>=420, 2, IF(P28>=360, 1, IF(P28>=300, 0, IF(P28>=240, -1, -2)))))) -> 1 | P28: =sum(T28:Z28) -> 388 | Q28: =R28*6 -> 776 | R28: =iferror(P28/S28,"0") -> 129.33333 | S28: =count(T28:Z28) -> 3 | T28: ー | U28: ー | V28: ー | W28: ー | X28: 138 | Y28: 176 | Z28: 74 | AA28: =Vlookup(B28,'セッション実施状況管理'!$A:$R,17,false) | AB28: =(YEAR(TODAY()) - YEAR($AA28)) * 12 + (MONTH(TODAY()) - MONTH($AA28)) -> 1514 | AC28: =IF( OR(AB28=3, AB28=4, AB28=5, AB28=6), "1", "2" ) -> 2
B29: 11 | C29: =vlookup(B29,'セッション実施状況管理'!$A:$U,8,false) -> かわかみまさと | D29: =vlookup(B29,'セッション実施状況管理'!$A:$I,9,false) -> satojitan_recipe | E29: https://docs.google.com/spreadsheets/d/1CJI2fnbP3Vn3MKDn_UAnEjJBoPYa8N4JiLFiYx3GYSs/edit?usp=sharing | F29: =vlookup(B29,'セッション実施状況管理'!$A:$U,20,false) -> 野村佑佳 | G29: =vlookup(B29,'セッション実施状況管理'!$A:$U,20,false) -> 野村佑佳 | H29: ='コーチング報酬管理'!G18 -> 13 | I29: =iferror(vlookup(B29,'セッション実施状況管理'!$A:$B,2,false),"") -> 卒業 | J29: 0 | K29: 0 | L29: =VLOOKUP(B29,'新 月次投稿数'!$A:$N,13,false) -> 14 | M29: =IF(L29>=120, 3, IF(L29>=100, 2, IF(L29>=80, 1, IF(L29>=60, 0, IF(L29>=40, -1, IF(L29>=20, -2, -3)))))) -> -3 | N29: =IF(Q29>=540, 4, IF(Q29>=480, 3, IF(Q29>=420, 2, IF(Q29>=360, 1, IF(Q29>=300, 0, IF(Q29>=240, -1, -2)))))) -> 1 | O29: =IF(P29>=540, 4, IF(P29>=480, 3, IF(P29>=420, 2, IF(P29>=360, 1, IF(P29>=300, 0, IF(P29>=240, -1, -2)))))) -> -1 | P29: =sum(T29:Z29) -> 252 | Q29: =R29*6 -> 378 | R29: =iferror(P29/S29,"0") -> 63 | S29: =count(T29:Z29) -> 4 | T29: ー | U29: ー | V29: ー | W29: 83 | X29: 79 | Y29: 90 | Z29: 0 | AA29: =Vlookup(B29,'セッション実施状況管理'!$A:$R,17,false) | AB29: =(YEAR(TODAY()) - YEAR($AA29)) * 12 + (MONTH(TODAY()) - MONTH($AA29)) -> 1514 | AC29: =IF( OR(AB29=3, AB29=4, AB29=5, AB29=6), "1", "2" ) -> 2
